Workbook

Sheet 06 tháng đầu năm
A1: NGÀY | B1: THÁNG | C1: VỤ CHÁY VÀ CNCH | G1: CÔNG TÁC KIỂM TRA | P1: TUYÊN TRUYỀN PCCC | U1: HUẤN LUYỆN PCCC | X1: PACC&CNCH của cơ sở theo mẫu PC06 | Z1: PACC&CNCH của CQ CA theo mẫu PC08 | AB1: PA CNCH của CQ CA theo mẫu PC09 | AD1: PACC&CNCH của phương tiện giao thông theo mẫu PC07
C2: VỤ CHÁY CÓ THỐNG KÊ | D2: SỰ CỐ LIÊN QUAN ĐẾN PCCC&CNCH | E2: VỤ CHÁY CHI VIỆN | F2: CNCH | G2: NHÓM I | H2: NHÓM II | I2: ĐỘT XUẤT | J2: HƯỚNG DẪN | K2: KIẾN NGHỊ | L2: XỬ PHẠT | M2: TIỀN PHẠT (triệu đồng) | N2: ĐÌNH CHỈ | O2: PHỤC HỒI | P2: TIN BÀI, PHÓNG SỰ | Q2: SỐ LỚP TUYÊN TRUYỀN | R2: SỐ NGƯỜI THAM DỰ | S2: SỐ KHUYẾN CÁO, TỜ RƠI ĐÃ PHÁT | T2: CÀI APP HELP 114 | U2: SỐ LỚP HUẤN LUYỆN | V2: SỐ NGƯỜI THAM DỰ | W2: CẤP GIẤY CHỨNG NHẬN HUẤN LUYỆN NGHIỆP VỤ PCCC | X2: SỐ PA XÂY DỰNG VÀ PHÊ DUYỆT | Y2: SỐ PA ĐƯỢC THỰC TẬP | Z2: SỐ PA XÂY DỰNG VÀ PHÊ DUYỆT | AA2: SỐ PA ĐƯỢC THỰC TẬP | AB2: SỐ PA XÂY DỰNG VÀ PHÊ DUYỆT | AC2: SỐ PA ĐƯỢC THỰC TẬP | AD2: SỐ PA XÂY DỰNG VÀ PHÊ DUYỆT | AE2: SỐ PA ĐƯỢC THỰC TẬP
A3: 06 tháng đầu năm | C3: 6 | D3: 0 | E3: 0 | F3: 7 | G3: 712 | I3: 57 | J3: 5360 | K3: 226 | L3: 138 | M3: 4103.7 | P3: 16 | Q3: 70 | R3: 17266 | U3: 52 | V3: 2020 | AA3: 30
B4: 7 | C4: 5 | D4: 0 | E4: 3 | F4: 0 | G4: 1 | J4: 6 | P4: 2 | Q4: 9 | R4: 2689 | S4: 2196 | T4: 297 | U4: 33 | V4: 1010 | W4: 238 | AA4: 3
B5: 8 | C5: 3 | D5: 6 | E5: 2 | F5: 1 | G5: 0 | H5: 0 | I5: 0 | J5: 0 | K5: 0 | L5: 0 | M5: 0 | N5: 0 | O5: 0 | P5: 0 | Q5: 69 | R5: 11705 | S5: 11502 | T5: 6929 | U5: 0 | V5: 0 | W5: 0 | X5: 0 | Y5: 0 | Z5: 0 | AA5: 0 | AB5: 0 | AC5: 0 | AD5: 0 | AE5: 0
B6: 9 | C6: 3 | D6: 6 | E6: 2 | F6: 1 | G6: 53 | H6: 30 | I6: 0 | J6: 0 | K6: 0 | L6: 0 | M6: 0 | N6: 0 | O6: 0 | P6: 2 | Q6: 4 | R6: 1850 | T6: 1850 | U6: 0 | V6: 0 | W6: 0 | X6: 0 | Y6: 0 | Z6: 0 | AA6: 0 | AB6: 0 | AC6: 0 | AD6: 0 | AE6: 0
B7: 10 | C7: 1 | D7: 0 | E7: 1 | F7: 1 | G7: 160 | H7: 41 | I7: 0 | J7: 1206 | K7: 0 | L7: 0 | M7: 0 | N7: 0 | O7: 0 | P7: 1 | Q7: 8 | R7: 9165 | S7: 357 | T7: 10318
B8: 11 | C8: 1 | D8: 5 | E8: 0 | F8: 0 | G8: 170 | H8: 149 | I8: 0 | J8: 1920 | K8: 0 | L8: 0 | M8: 0 | N8: 0 | O8: 0 | P8: 3 | Q8: 7 | R8: 4384 | S8: 362 | T8: 3360 | U8: 5 | V8: 307 | W8: 0 | X8: 0 | Y8: 0 | Z8: 1 | AA8: 1 | AB8: 0 | AC8: 0 | AD8: 0 | AE8: 0
B9: 12 | C9: 1 | D9: 5 | E9: 1 | F9: 2 | G9: 38 | H9: 80 | I9: 1 | J9: 758 | K9: 3 | L9: 2 | M9: 50 | N9: 0 | O9: 0 | P9: 1 | Q9: 4 | R9: 1975 | S9: 200 | T9: 200 | U9: 21 | V9: 1217 | W9: 0 | X9: 11 | Y9: 0 | Z9: 9 | AA9: 4 | AB9: 2 | AC9: 0 | AD9: 0 | AE9: 0
B10: Tổng | C10: =sum(C3:C9) -> 20 | D10: =sum(D3:D9) -> 22 | E10: =sum(E3:E9) -> 9 | F10: =sum(F3:F9) -> 12 | G10: =sum(G3:G9) -> 1134 | H10: =sum(H3:H9) -> 300 | I10: =sum(I3:I9) -> 58 | J10: =sum(J3:J9) -> 9250 | ... AE10: =sum(AE3:AE9) -> 0
F11: Từ 1/7 đến 13/11 | G11: =SUM(G5:G9) -> 421 | H11: =SUM(H5:H9) -> 300
F12: Từ 1/7 đến 13/12 | G12: =SUM(G11:H11) -> 721

Sheet BC NGÀY 1
A1: NGÀY | B1: THÁNG | C1: VỤ CHÁY VÀ CNCH | G1: CÔNG TÁC KIỂM TRA | P1: TUYÊN TRUYỀN PCCC | T1: HUẤN LUYỆN PCCC | V1: TỔNG TUYÊN TRUYỀN/HUẤN LUYỆN | X1: PACC&CNCH của cơ sở theo mẫu PC06 | Z1: PACC&CNCH của CQ CA theo mẫu PC08 | AB1: PA CNCH của CQ CA theo mẫu PC09 | AD1: PACC&CNCH của phương tiện giao thông theo mẫu PC07
C2: VỤ CHÁY CÓ THỐNG KÊ | D2: SỰ CỐ LIÊN QUAN ĐẾN PCCC&CNCH | E2: VỤ CHÁY CHI VIỆN | F2: CNCH | G2: NHÓM I | H2: NHÓM II | I2: ĐỘT XUẤT | J2: HƯỚNG DẪN | K2: KIẾN NGHỊ | L2: XỬ PHẠT | M2: TIỀN PHẠT (triệu đồng) | N2: ĐÌNH CHỈ | O2: PHỤC HỒI | P2: TIN BÀI, PHÓNG SỰ | Q2: SỐ LỚP TUYÊN TRUYỀN | R2: SỐ NGƯỜI THAM DỰ | S2: SỐ KHUYẾN CÁO, TỜ RƠI ĐÃ PHÁT | T2: SỐ LỚP HUẤN LUYỆN | U2: SỐ NGƯỜI THAM DỰ | V2: SỐ LỚP | W2: SỐ NGƯỜI THAM DỰ | X2: SỐ PA XÂY DỰNG VÀ PHÊ DUYỆT | Y2: SỐ PA ĐƯỢC THỰC TẬP | Z2: SỐ PA XÂY DỰNG VÀ PHÊ DUYỆT | AA2: SỐ PA ĐƯỢC THỰC TẬP | AB2: SỐ PA XÂY DỰNG VÀ PHÊ DUYỆT | AC2: SỐ PA ĐƯỢC THỰC TẬP | AD2: SỐ PA XÂY DỰNG VÀ PHÊ DUYỆT | AE2: SỐ PA ĐƯỢC THỰC TẬP
A3: 15 | B3: 11 | C3: 0 | D3: 1 | E3: 0 | F3: 0 | G3: 3 | H3: 5 | J3: 51 | K3: 0 | L3: 0 | M3: 0 | N3: 0 | O3: 0 | P3: 0 | Q3: 0 | R3: 0 | S3: 0 | T3: 0 | U3: 0 | V3: =Q3+T3 -> 0 | W3: =R3+U3 -> 0 | X3: =sum(G3:H3) -> 8 | Y3: 0 | Z3: 0 | AA3: 0 | AB3: 0 | AC3: 0 | AD3: 0 | AE3: 0
A4: 16 | B4: 11 | C4: 0 | D4: 0 | E4: 0 | F4: 1 | G4: 2 | H4: 7 | J4: 48 | K4: 0 | L4: 0 | M4: 0 | N4: 0 | O4: 0 | P4: 0 | Q4: 0 | R4: 0 | S4: 0 | T4: 0 | U4: 0 | V4: =Q4+T4 -> 0 | W4: =R4+U4 -> 0 | X4: =sum(G4:H4) -> 9 | Y4: 0 | Z4: 0 | AA4: 0 | AB4: 0 | AC4: 0 | AD4: 0 | AE4: 0
A5: 17 | B5: 11 | C5: 0 | D5: 0 | E5: 0 | F5: 0 | G5: 0 | H5: 0 | J5: =sum(G5:H5)*6 -> 0 | K5: 0 | L5: 0 | M5: 0 | N5: 0 | O5: 0 | P5: 0 | Q5: 0 | R5: 0 | S5: 0 | T5: 0 | U5: 0 | V5: =Q5+T5 -> 0 | W5: =R5+U5 -> 0 | X5: =sum(G5:H5) -> 0 | Y5: 0 | Z5: 0 | AA5: 0 | AB5: 0 | AC5: 0 | AD5: 0 | AE5: 0
A6: 18 | B6: 11 | C6: 0 | D6: 0 | E6: 0 | F6: 0 | G6: 1 | H6: 1 | J6: =sum(G6:H6)*6 -> 12 | K6: 0 | L6: 0 | M6: 0 | N6: 0 | O6: 0 | P6: 0 | Q6: 0 | R6: 0 | S6: 0 | T6: 0 | U6: 0 | V6: =Q6+T6 -> 0 | W6: =R6+U6 -> 0 | X6: =sum(G6:H6) -> 2 | Y6: 0 | Z6: 0 | AA6: 0 | AB6: 0 | AC6: 0 | AD6: 0 | AE6: 0
A7: 19 | B7: 11 | C7: 0 | D7: 0 | E7: 0 | F7: 0 | G7: 0 | H7: 0 | J7: =sum(G7:H7)*6 -> 0 | K7: 0 | L7: 0 | M7: 0 | N7: 0 | O7: 0 | P7: 0 | Q7: 1 | R7: 1200 | S7: 0 | T7: 0 | U7: 0 | V7: =Q7+T7 -> 1 | W7: =R7+U7 -> 1200 | X7: =sum(G7:H7) -> 0 | Y7: 0 | Z7: 0 | AA7: 0 | AB7: 0 | AC7: 0 | AD7: 0 | AE7: 0
A8: 20 | B8: 11 | C8: 0 | D8: 0 | E8: 0 | F8: 0 | G8: 0 | H8: 2 | J8: 6 | K8: 0 | L8: 0 | M8: 0 | N8: 0 | O8: 0 | P8: 0 | Q8: 0 | R8: 0 | S8: 0 | T8: 0 | U8: 0 | V8: =Q8+T8 -> 0 | W8: =R8+U8 -> 0 | X8: =sum(G8:H8) -> 2 | Y8: 0 | Z8: 0 | AA8: 0 | AB8: 0 | AC8: 0 | AD8: 0 | AE8: 0
A9: 21 | B9: 11 | C9: 0 | D9: 0 | E9: 0 | F9: 0 | G9: 2 | H9: 0 | J9: 22 | K9: 0 | L9: 0 | M9: 0 | N9: 0 | O9: 0 | P9: 0 | Q9: 0 | R9: 0 | S9: 0 | T9: 0 | U9: 0 | V9: =Q9+T9 -> 0 | W9: =R9+U9 -> 0 | X9: =sum(G9:H9) -> 2 | Y9: 0 | Z9: 0 | AA9: 0 | AB9: 0 | AC9: 0 | AD9: 0 | AE9: 0
A10: 22 | B10: 11 | C10: 0 | D10: 0 | E10: 0 | F10: 0 | G10: 0 | H10: 0 | J10: 0 | K10: 0 | L10: 0 | M10: 0 | N10: 0 | O10: 0 | P10: 0 | Q10: 0 | R10: 0 | S10: 0 | T10: 0 | U10: 0 | V10: =Q10+T10 -> 0 | W10: =R10+U10 -> 0 | X10: =sum(G10:H10) -> 0 | Y10: 0 | Z10: 0 | AA10: 0 | AB10: 0 | AC10: 0 | AD10: 0 | AE10: 0
A11: 23 | B11: 11 | C11: 1 | D11: 1 | E11: 0 | F11: 0 | G11: 0 | H11: 0 | J11: 0 | K11: 0 | L11: 0 | M11: 0 | N11: 0 | O11: 0 | P11: 0 | Q11: 0 | R11: 0 | S11: 0 | T11: 0 | U11: 0 | V11: =Q11+T11 -> 0 | W11: =R11+U11 -> 0 | X11: =sum(G11:H11) -> 0 | Y11: 0 | Z11: 0 | AA11: 0 | AB11: 0 | AC11: 0 | AD11: 0 | AE11: 0
A12: 24 | B12: 11 | C12: 0 | D12: 0 | E12: 0 | F12: 0 | G12: 0 | H12: 0 | J12: 0 | K12: 0 | L12: 0 | M12: 0 | N12: 0 | O12: 0 | P12: 0 | Q12: 0 | R12: 0 | S12: 0 | T12: 0 | U12: 0 | V12: =Q12+T12 -> 0 | W12: =R12+U12 -> 0 | X12: =sum(G12:H12) -> 0 | Y12: 0 | Z12: 0 | AA12: 0 | AB12: 0 | AC12: 0 | AD12: 0 | AE12: 0
A13: 25 | B13: 11 | C13: 0 | D13: 1 | E13: 0 | F13: 0 | G13: 0 | H13: 0 | J13: 0 | K13: 0 | L13: 0 | M13: 0 | N13: 0 | O13: 0 | P13: 0 | Q13: 0 | R13: 0 | S13: 0 | T13: 0 | U13: 0 | V13: =Q13+T13 -> 0 | W13: =R13+U13 -> 0 | X13: =sum(G13:H13) -> 0 | Y13: 0 | Z13: 0 | AA13: 0 | AB13: 0 | AC13: 0 | AD13: 0 | AE13: 0
A14: 26 | B14: 11 | C14: 0 | D14: 0 | E14: 0 | F14: 0 | G14: 1 | H14: 0 | J14: 5 | K14: 0 | L14: 0 | M14: 0 | N14: 0 | O14: 0 | P14: 0 | Q14: 0 | R14: 0 | S14: 0 | T14: 0 | U14: 0 | V14: =Q14+T14 -> 0 | W14: =R14+U14 -> 0 | X14: =sum(G14:H14) -> 1 | Y14: 0 | Z14: 0 | AA14: 0 | AB14: 0 | AC14: 0 | AD14: 0 | AE14: 0
A15: 27 | B15: 11 | C15: 0 | D15: 0 | E15: 0 | F15: 0 | G15: 0 | H15: 3 | J15: 22 | K15: 0 | L15: 0 | M15: 0 | N15: 0 | O15: 0 | P15: 0 | Q15: 0 | R15: 0 | S15: 0 | T15: 6 | U15: 310 | V15: =Q15+T15 -> 6 | W15: =R15+U15 -> 310 | X15: =sum(G15:H15) -> 3 | Y15: 0 | Z15: 0 | AA15: 0 | AB15: 0 | AC15: 0 | AD15: 0 | AE15: 0
A16: 28 | B16: 11 | C16: 0 | D16: 0 | E16: 0 | F16: 0 | G16: 1 | H16: 5 | J16: 42 | K16: 0 | L16: 0 | M16: 0 | N16: 0 | O16: 0 | P16: 1 | Q16: 0 | R16: 0 | S16: 0 | T16: 0 | U16: 0 | V16: =Q16+T16 -> 0 | W16: =R16+U16 -> 0 | X16: =sum(G16:H16) -> 6 | Y16: 0 | Z16: 0 | AA16: 0 | AB16: 0 | AC16: 0 | AD16: 0 | AE16: 0
A17: 29 | B17: 11 | C17: 0 | D17: 0 | E17: 0 | F17: 0 | G17: 1 | H17: 6 | J17: 42 | K17: 0 | L17: 0 | M17: 0 | N17: 0 | O17: 0 | P17: 0 | Q17: 1 | R17: 455 | S17: 0 | T17: 2 | U17: 51 | V17: =Q17+T17 -> 3 | W17: =R17+U17 -> 506 | X17: =sum(G17:H17) -> 7 | Y17: 0 | Z17: 0 | AA17: 0 | AB17: 0 | AC17: 0 | AD17: 0 | AE17: 0
A18: 30 | B18: 11 | C18: 0 | D18: 0 | E18: 0 | F18: 0 | G18: 0 | H18: 0 | J18: 0 | K18: 0 | L18: 0 | M18: 0 | N18: 0 | O18: 0 | P18: 0 | Q18: 1 | R18: 120 | S18: 0 | T18: 2 | U18: 61 | V18: =Q18+T18 -> 3 | W18: =R18+U18 -> 181 | X18: =sum(G18:H18) -> 0 | Y18: 0 | Z18: 1 | AA18: 1 | AB18: 0 | AC18: 0 | AD18: 0 | AE18: 0
A19: 1 | B19: 12 | C19: 0 | D19: 0 | E19: 0 | F19: 0 | G19: 0 | H19: 0 | J19: 0 | K19: 0 | L19: 0 | M19: 0 | N19: 0 | O19: 0 | P19: 0 | Q19: 0 | R19: 0 | S19: 0 | T19: 0 | U19: 0 | V19: =Q19+T19 -> 0 | W19: =R19+U19 -> 0 | X19: =sum(G19:H19) -> 0 | Y19: 0 | Z19: 0 | AA19: 0 | AB19: 0 | AC19: 0 | AD19: 0 | AE19: 0
... A27: 9 | B27: 12 | C27: 0 | D27: 1 | E27: 0 | F27: 0 | G27: 0 | H27: 0 | J27: 0 | K27: 0 | L27: 0 | M27: 0 | N27: 0 | O27: 0 | P27: 0 | Q27: 0 | R27: 0 | S27: 0 | T27: 1 | U27: 25 | V27: =Q27+T27 -> 1 | W27: =R27+U27 -> 25 | X27: =sum(G27:H27) -> 0 | Y27: 0 | Z27: 0 | AA27: 0 | AB27: 0 | AC27: 0 | AD27: 0 | AE27: 0
A28: 10 | B28: 12 | C28: 0 | D28: 1 | E28: 0 | F28: 0 | G28: 4 | H28: 8 | I28: 1 | J28: 87 | K28: 1 | L28: 1 | M28: 50 | N28: 0 | O28: 0 | P28: 0 | Q28: 0 | R28: 0 | S28: 0 | T28: 1 | U28: 25 | V28: =Q28+T28 -> 1 | W28: =R28+U28 -> 25 | X28: =sum(G28:H28) -> 12 | Y28: 0 | Z28: 1 | AA28: 1 | AB28: 0 | AC28: 0 | AD28: 0 | AE28: 0
A29: 11 | B29: 12 | C29: 0 | D29: 0 | E29: 0 | F29: 0 | G29: 10 | H29: 9 | I29: 0 | J29: 146 | K29: 0 | L29: 0 | M29: 0 | N29: 0 | O29: 0 | P29: 0 | Q29: 1 | R29: 200 | S29: 200 | T29: 3 | U29: 247 | V29: =Q29+T29 -> 4 | W29: =R29+U29 -> 447 | X29: =sum(G29:H29) -> 19 | Y29: 0 | Z29: 1 | AA29: 1 | AB29: 0 | AC29: 0 | AD29: 0 | AE29: 0
A30: 12 | B30: 12 | C30: 0 | D30: 0 | E30: 0 | F30: 0 | G30: 4 | H30: 6 | I30: 0 | J30: 45 | K30: 2 | L30: 1 | M30: 84 | N30: 0 | O30: 0 | P30: 0 | Q30: 0 | R30: 0 | S30: 0 | T30: 0 | U30: 0 | V30: =Q30+T30 -> 0 | W30: =R30+U30 -> 0 | X30: =sum(G30:H30) -> 10 | Y30: 0 | Z30: 0 | AA30: 0 | AB30: 0 | AC30: 0 | AD30: 0 | AE30: 0
A31: 13 | B31: 12 | C31: 0 | D31: 0 | E31: 0 | F31: 1 | G31: 2 | H31: 5 | I31: 0 | J31: 49 | K31: 0 | L31: 0 | M31: 0 | N31: 0 | O31: 0 | P31: 0 | Q31: 0 | R31: 0 | S31: 0 | T31: 6 | U31: 178 | V31: =Q31+T31 -> 6 | W31: =R31+U31 -> 178 | X31: 7 | Y31: 0 | Z31: 0 | AA31: 0 | AB31: 0 | AC31: 0 | AD31: 0 | AE31: 0
A32: 14 | B32: 12 | C32: 0 | D32: 0 | E32: 0 | F32: 0 | G32: 0 | H32: 0 | I32: 0 | J32: 0 | K32: 0 | L32: 0 | M32: 0 | N32: 0 | O32: 0 | P32: 0 | Q32: 0 | R32: 0 | S32: 0 | T32: 2 | U32: 173 | V32: =Q32+T32 -> 2 | W32: =R32+U32 -> 173 | X32: 0 | Y32: 0 | Z32: 0 | AA32: 0 | AB32: 0 | AC32: 0 | AD32: 0 | AE32: 0
A33: 15 | B33: 12 | C33: 0 | D33: 0 | E33: 0 | F33: 0 | G33: 0 | H33: 0 | I33: 0 | J33: 0 | K33: 0 | L33: 0 | M33: 0 | N33: 0 | O33: 0 | P33: 0 | Q33: 1 | R33: 1900 | S33: 0 | T33: 3 | U33: 166 | V33: =Q33+T33 -> 4 | W33: =R33+U33 -> 2066 | X33: 0 | Y33: 0 | Z33: 1 | AA33: 1 | AB33: 0 | AC33: 0 | AD33: 0 | AE33: 0
A34: 16 | B34: 12 | C34: 0 | D34: 0 | E34: 0 | F34: 0 | G34: 0 | H34: 0 | I34: 0 | J34: 0 | K34: 0 | L34: 0 | M34: 0 | N34: 0 | O34: 0 | P34: 0 | Q34: 0 | R34: 0 | S34: 0 | T34: 2 | U34: 60 | V34: =Q34+T34 -> 2 | W34: =R34+U34 -> 60 | X34: 0 | Y34: 0 | Z34: 1 | AA34: 1 | AB34: 0 | AC34: 0 | AD34: 0 | AE34: 0
A35: 17 | B35: 12 | C35: 0 | D35: 1 | E35: 0 | F35: 0 | G35: 4 | H35: 3 | I35: 0 | J35: 49 | K35: 1 | L35: 1 | M35: 4 | N35: 0 | O35: 0 | P35: 0 | Q35: 0 | R35: 0 | S35: 0 | T35: 2 | U35: 86 | V35: =Q35+T35 -> 2 | W35: =R35+U35 -> 86 | X35: 0 | Y35: 0 | Z35: 1 | AA35: 1 | AB35: 0 | AC35: 0 | AD35: 0 | AE35: 0
A36: 18 | B36: 12 | C36: 0 | D36: 0 | E36: 0 | F36: 0 | G36: 4 | H36: 1 | I36: 0 | J36: 61 | K36: 0 | L36: 0 | M36: 0 | N36: 0 | O36: 0 | P36: 0 | Q36: 0 | R36: 0 | S36: 0 | T36: 2 | U36: 106 | V36: =Q36+T36 -> 2 | W36: =R36+U36 -> 106 | X36: 0 | Y36: 0 | Z36: 1 | AA36: 1 | AB36: 0 | AC36: 0 | AD36: 0 | AE36: 0
A37: 19 | B37: 12 | C37: 0 | D37: 2 | E37: 0 | F37: 0 | G37: 2 | H37: 1 | I37: 0 | J37: 0 | K37: 0 | L37: 0 | M37: 0 | N37: 0 | O37: 0 | P37: 0 | Q37: 0 | R37: 0 | S37: 0 | T37: 4 | U37: 150 | V37: =Q37+T37 -> 4 | W37: =R37+U37 -> 150 | X37: =sum(G37:H37) -> 3 | Y37: =sum(G37:H37) -> 3 | Z37: 2 | AA37: 2 | AB37: 0 | AC37: 0 | AD37: 0 | AE37: 0
A38: 20 | B38: 12 | C38: 0 | D38: 0 | E38: 0 | F38: 0 | G38: 2 | H38: 4 | I38: 0 | J38: 41 | K38: 0 | L38: 0 | M38: 0 | N38: 0 | O38: 0 | P38: 0 | Q38: 0 | R38: 0 | S38: 0 | T38: 5 | U38: 136 | V38: =Q38+T38 -> 5 | W38: =R38+U38 -> 136 | X38: =sum(G38:H38) -> 6 | Y38: =sum(G38:H38) -> 6 | Z38: 1 | AA38: 1 | AB38: 0 | AC38: 0 | AD38: 0 | AE38: 0
A39: 21 | B39: 12 | C39: 0 | D39: 1 | E39: 0 | F39: 0 | G39: 0 | H39: 0 | I39: 0 | J39: 0 | K39: 0 | L39: 0 | M39: 0 | N39: 0 | O39: 0 | P39: 0 | Q39: 0 | R39: 0 | S39: 0 | T39: 9 | U39: 449 | V39: =Q39+T39 -> 9 | W39: =R39+U39 -> 449 | X39: =sum(G39:H39) -> 0 | Y39: =sum(G39:H39) -> 0 | Z39: 1 | AA39: 1 | AB39: 0 | AC39: 0 | AD39: 0 | AE39: 0
A40: 22 | B40: 12 | C40: 0 | D40: 0 | E40: 0 | F40: 0 | G40: 0 | H40: 0 | I40: 0 | J40: 0 | K40: 0 | L40: 0 | M40: 0 | N40: 0 | O40: 0 | P40: 0 | Q40: 2 | R40: 400 | S40: 100 | T40: 0 | U40: 0 | V40: =Q40+T40 -> 2 | W40: =R40+U40 -> 400 | X40: =sum(G40:H40) -> 0 | Y40: =sum(G40:H40) -> 0 | Z40: 1 | AA40: 1 | AB40: 0 | AC40: 0 | AD40: 0 | AE40: 0
A41: 23 | B41: 12 | C41: 0 | D41: 0 | E41: 1 | F41: 0 | G41: 0 | H41: 0 | I41: 0 | J41: 0 | K41: 0 | L41: 0 | M41: 0 | N41: 0 | O41: 0 | P41: 1 | Q41: 0 | R41: 0 | S41: 0 | T41: 5 | U41: 244 | V41: =Q41+T41 -> 5 | W41: =R41+U41 -> 244 | X41: =sum(G41:H41) -> 0 | Y41: =sum(G41:H41) -> 0 | Z41: 1 | AA41: 1 | AB41: 0 | AC41: 0 | AD41: 0 | AE41: 0
A42: 24 | B42: 12 | C42: 0 | D42: 1 | E42: 0 | F42: 0 | G42: 0 | H42: 0 | I42: 0 | J42: 0 | K42: 0 | L42: 0 | M42: 0 | N42: 0 | O42: 0 | P42: 0 | Q42: 0 | R42: 0 | S42: 0 | T42: 5 | U42: 210 | V42: =Q42+T42 -> 5 | W42: =R42+U42 -> 210 | X42: =sum(G42:H42) -> 0 | Y42: =sum(G42:H42) -> 0 | Z42: 1 | AA42: 1 | AB42: 0 | AC42: 0 | AD42: 0 | AE42: 0
A43: 25 | B43: 12 | C43: 0 | D43: 0 | E43: 0 | F43: 1 | G43: 0 | H43: 0 | I43: 0 | J43: 0 | K43: 0 | L43: 0 | M43: 0 | N43: 0 | O43: 0 | P43: 0 | Q43: 0 | R43: 0 | S43: 0 | T43: 3 | U43: 312 | V43: =Q43+T43 -> 3 | W43: =R43+U43 -> 312 | X43: =sum(G43:H43) -> 0 | Y43: =sum(G43:H43) -> 0 | Z43: 1 | AA43: 1 | AB43: 0 | AC43: 0 | AD43: 0 | AE43: 0
A44: 26 | B44: 12 | C44: 0 | D44: 0 | E44: 0 | F44: 0 | G44: 2 | H44: 0 | I44: 0 | J44: 18 | K44: 0 | L44: 0 | M44: 0 | N44: 0 | O44: 0 | P44: 0 | Q44: 0 | R44: 0 | S44: 0 | T44: 3 | U44: 134 | V44: =Q44+T44 -> 3 | W44: =R44+U44 -> 134 | X44: 0 | Y44: 0 | Z44: 0 | AA44: 0 | AB44: 0 | AC44: 0 | AD44: 0 | AE44: 0
A45: 27 | B45: 12 | C45: 0 | D45: 0 | E45: 0 | F45: 0 | G45: 4 | H45: 0 | I45: 0 | J45: 0 | K45: 0 | L45: 0 | M45: 0 | N45: 0 | O45: 0 | P45: 2 | Q45: 3 | R45: 1135 | S45: 0 | T45: 7 | U45: 166 | V45: =Q45+T45 -> 10 | W45: =R45+U45 -> 1301 | X45: 0 | Y45: 0 | Z45: 1 | AA45: 1 | AB45: 0 | AC45: 0 | AD45: 0 | AE45: 0
A46: 28 | B46: 12 | C46: 0 | D46: 0 | E46: 0 | F46: 0 | G46: 6 | H46: 5 | I46: 0 | J46: 0 | K46: 0 | L46: 0 | M46: 0 | N46: 0 | O46: 0 | P46: 0 | Q46: 2 | R46: 160 | S46: 0 | T46: 7 | U46: 438 | V46: =Q46+T46 -> 9 | W46: =R46+U46 -> 598 | X46: =sum(G46:H46) -> 11 | Y46: =sum(G46:H46) -> 11 | Z46: 1 | AA46: 1 | AB46: 0 | AC46: 0 | AD46: 0 | AE46: 0
A47: 29 | B47: 12 | C47: 0 | D47: 0 | E47: 0 | F47: 0 | G47: 0 | H47: 0 | I47: 0 | J47: 0 | K47: 0 | L47: 0 | M47: 0 | N47: 0 | O47: 0 | P47: 0 | Q47: 2 | R47: 458 | S47: 2100 | T47: 0 | U47: 0 | V47: =Q47+T47 -> 2 | W47: =R47+U47 -> 458 | X47: =sum(G47:H47) -> 0 | Y47: =sum(G47:H47) -> 0 | Z47: 0 | AA47: 0 | AB47: 0 | AC47: 0 | AD47: 0 | AE47: 0
...

Sheet BC NGÀY
A1: NGÀY | B1: THÁNG | C1: VỤ CHÁY VÀ CNCH | G1: CÔNG TÁC KIỂM TRA | Q1: TUYÊN TRUYỀN PCCC | V1: HUẤN LUYỆN PCCC | X1: TỔNG TUYÊN TRUYỀN/HUẤN LUYỆN | Z1: PACC&CNCH của cơ sở theo mẫu PC06 | AB1: PACC&CNCH của CQ CA theo mẫu PC08 | AD1: PA CNCH của CQ CA theo mẫu PC09 | AF1: PACC&CNCH của phương tiện giao thông theo mẫu PC07 | AH1: Ghi chú
C2: VỤ CHÁY THỐNG KÊ | D2: SCLQ ĐẾN PCCC& CNCH | E2: CHI VIỆN | F2: CNCH | G2: ĐỊNH KỲ | I2: ĐỘT XUẤT | K2: HƯỚNG DẪN | L2: KIẾN NGHỊ | M2: XỬ PHẠT | N2: TIỀN PHẠT (triệu đồng) | O2: ĐÌNH CHỈ | P2: PHỤC HỒI | Q2: TIN BÀI | R2: PHÓNG SỰ | S2: SỐ LỚP TUYÊN TRUYỀN | T2: SỐ NGƯỜI THAM DỰ | U2: SỐ KHUYẾN CÁO, TỜ RƠI ĐÃ PHÁT | V2: SỐ LỚP HUẤN LUYỆN | W2: SỐ NGƯỜI THAM DỰ | X2: SỐ LỚP | Y2: SỐ NGƯỜI THAM DỰ | Z2: SỐ PA XÂY DỰNG VÀ PHÊ DUYỆT | AA2: SỐ PA ĐƯỢC THỰC TẬP | AB2: SỐ PA XÂY DỰNG VÀ PHÊ DUYỆT | AC2: SỐ PA ĐƯỢC THỰC TẬP | AD2: SỐ PA XÂY DỰNG VÀ PHÊ DUYỆT | AE2: SỐ PA ĐƯỢC THỰC TẬP | AF2: SỐ PA XÂY DỰNG VÀ PHÊ DUYỆT | AG2: SỐ PA ĐƯỢC THỰC TẬP
G3: NHÓM I | H3: NHÓM II | I3: NHÓM I | J3: NHÓM II
A4: 1 | B4: 3 | C4: 0 | D4: 0 | E4: 0 | F4: 0 | G4: 0 | H4: 0 | I4: 0 | J4: 0 | K4: 0 | L4: 0 | M4: 0 | N4: 0 | O4: 0 | P4: 0 | Q4: 0 | R4: 0 | S4: 0 | T4: 0 | U4: 0 | V4: 0 | W4: 0 | X4: 0 | Y4: 0 | Z4: 0 | AA4: 0 | AB4: 0 | AC4: 0 | AD4: 0 | AE4: 0 | AF4: 0 | AG4: 0
A5: 2 | B5: 3 | C5: 0 | D5: 0 | E5: 0 | F5: 1 | G5: 0 | H5: 0 | I5: 0 | J5: 0 | K5: 0 | L5: 0 | M5: 0 | N5: 0 | O5: 0 | P5: 0 | Q5: 0 | R5: 0 | S5: 0 | T5: 0 | U5: 0 | V5: 0 | W5: 0 | X5: 0 | Y5: 0 | Z5: 0 | AA5: 0 | AB5: 0 | AC5: 0 | AD5: 0 | AE5: 0 | AF5: 0 | AG5: 0
A6: 3 | B6: 3 | C6: 0 | D6: 0 | E6: 0 | F6: 1 | G6: 7 | H6: 2 | I6: 0 | J6: 0 | K6: 63 | L6: 0 | M6: 0 | N6: 0 | O6: 0 | P6: 0 | Q6: 0 | R6: 0 | S6: 1 | T6: 675 | U6: =T6 -> 675 | V6: 0 | W6: 0 | X6: =S6+V6 -> 1 | Y6: =T6+W6 -> 675 | Z6: =sum(G6:H6) -> 9 | AA6: =sum(G6:H6) -> 9 | AB6: 0 | AC6: 0 | AD6: 0 | AE6: 0 | AF6: 0 | AG6: 0
A7: 4 | B7: 3 | C7: 0 | D7: 0 | E7: 0 | F7: 0 | G7: 12 | H7: 2 | I7: 0 | J7: 0 | K7: 84 | L7: 0 | M7: 0 | N7: 0 | O7: 0 | P7: 0 | Q7: 0 | R7: 0 | S7: 0 | T7: 0 | U7: 0 | V7: 0 | W7: 0 | X7: =S7+V7 -> 0 | Y7: =T7+W7 -> 0 | Z7: =sum(G7:H7) -> 14 | AA7: =sum(G7:H7) -> 14 | AB7: 0 | AC7: 0 | AD7: 0 | AE7: 0 | AF7: 0 | AG7: 0
A8: 5 | B8: 3 | C8: 0 | D8: 0 | E8: 0 | F8: 0 | G8: 22 | H8: 6 | I8: 0 | J8: 0 | K8: 213 | L8: 0 | M8: 0 | N8: 0 | O8: 0 | P8: 0 | Q8: 0 | R8: 0 | S8: 0 | T8: 0 | U8: 0 | V8: 0 | W8: 0 | X8: =S8+V8 -> 0 | Y8: =T8+W8 -> 0 | Z8: =sum(G8:H8) -> 28 | AA8: =sum(G8:H8) -> 28 | AB8: 0 | AC8: 0 | AD8: 0 | AE8: 0 | AF8: 0 | AG8: 0
A9: 6 | B9: 3 | C9: 0 | D9: 0 | E9: 0 | F9: 0 | G9: 20 | H9: 6 | I9: 0 | J9: 0 | K9: 207 | L9: 0 | M9: 0 | N9: 0 | O9: 0 | P9: 0 | Q9: 0 | R9: 0 | S9: 0 | T9: 0 | U9: 0 | V9: 0 | W9: 0 | X9: =S9+V9 -> 0 | Y9: =T9+W9 -> 0 | Z9: =sum(G9:H9) -> 26 | AA9: =sum(G9:H9) -> 26 | AB9: 0 | AC9: 0 | AD9: 0 | AE9: 0 | AF9: 0 | AG9: 0
A10: 7 | B10: 3 | C10: 0 | D10: 0 | E10: 0 | F10: 0 | G10: 21 | H10: 25 | I10: 0 | J10: 0 | K10: 333 | L10: 0 | M10: 0 | N10: 0 | O10: 0 | P10: 0 | Q10: 0 | R10: 0 | S10: 0 | T10: 0 | U10: 0 | V10: 1 | W10: 37 | X10: =S10+V10 -> 1 | Y10: =T10+W10 -> 37 | Z10: =sum(G10:H10) -> 46 | AA10: =sum(G10:H10) -> 46 | AB10: 1 | AC10: 1 | AD10: 0 | AE10: 0 | AF10: 0 | AG10: 0
A11: 8 | B11: 3 | C11: 0 | D11: 0 | E11: 0 | F11: 0 | G11: 6 | H11: 8 | I11: 0 | J11: 0 | K11: 107 | L11: 0 | M11: 0 | N11: 0 | O11: 0 | P11: 0 | Q11: 0 | R11: 0 | S11: 0 | T11: 0 | U11: 0 | V11: 1 | W11: 30 | X11: =S11+V11 -> 1 | Y11: =T11+W11 -> 30 | Z11: =sum(G11:H11) -> 14 | AA11: =sum(G11:H11) -> 14 | AB11: 1 | AC11: 1 | AD11: 0 | AE11: 0 | AF11: 0 | AG11: 0
A12: 9 | B12: 3 | C12: 0 | D12: 0 | E12: 0 | F12: 0 | G12: 0 | H12: 0 | I12: 0 | J12: 0 | K12: 0 | L12: 0 | M12: 0 | N12: 0 | O12: 0 | P12: 0 | Q12: 0 | R12: 0 | S12: 0 | T12: 0 | U12: 0 | V12: 1 | W12: 78 | X12: =S12+V12 -> 1 | Y12: =T12+W12 -> 78 | Z12: =sum(G12:H12) -> 0 | AA12: =sum(G12:H12) -> 0 | AB12: 0 | AC12: 0 | AD12: 0 | AE12: 0 | AF12: 0 | AG12: 0
A13: 10 | B13: 3 | C13: 0 | D13: 0 | E13: 0 | F13: 0 | G13: 13 | H13: 5 | I13: 0 | J13: 0 | K13: 162 | L13: 0 | M13: 0 | N13: 0 | O13: 0 | P13: 0 | Q13: 0 | R13: 0 | S13: 0 | T13: 0 | U13: 0 | V13: 1 | W13: 25 | X13: =S13+V13 -> 1 | Y13: =T13+W13 -> 25 | Z13: =sum(G13:H13) -> 18 | AA13: =sum(G13:H13) -> 18 | AB13: 1 | AC13: 1 | AD13: 0 | AE13: 0 | AF13: 0 | AG13: 0
A14: 11 | B14: 3 | C14: 0 | D14: 0 | E14: 0 | F14: 0 | G14: 22 | H14: 18 | I14: 0 | J14: 0 | K14: 319 | L14: 0 | M14: 0 | N14: 0 | O14: 0 | P14: 0 | Q14: 0 | R14: 0 | S14: 0 | T14: 0 | U14: 0 | V14: 0 | W14: 0 | X14: =S14+V14 -> 0 | Y14: =T14+W14 -> 0 | Z14: =sum(G14:H14) -> 40 | AA14: =sum(G14:H14) -> 40 | AB14: 0 | AC14: 0 | AD14: 0 | AE14: 0 | AF14: 0 | AG14: 0
A15: 12 | B15: 3 | C15: 0 | D15: 0 | E15: 0 | F15: 0 | G15: 26 | H15: 17 | I15: 0 | J15: 0 | K15: 333 | L15: 0 | M15: 0 | N15: 0 | O15: 0 | P15: 0 | Q15: 0 | R15: 0 | S15: 0 | T15: 0 | U15: 0 | V15: 0 | W15: 0 | X15: =S15+V15 -> 0 | Y15: =T15+W15 -> 0 | Z15: =sum(G15:H15) -> 43 | AA15: =sum(G15:H15) -> 43 | AB15: 0 | AC15: 0 | AD15: 0 | AE15: 0 | AF15: 0 | AG15: 0
A16: 13 | B16: 3 | C16: 0 | D16: 0 | E16: 0 | F16: 0 | G16: 18 | H16: 12 | I16: 0 | J16: 0 | K16: 249 | L16: 0 | M16: 0 | N16: 0 | O16: 0 | P16: 0 | Q16: 1 | R16: 0 | S16: 1 | T16: 100 | U16: 100 | V16: 0 | W16: 0 | X16: =S16+V16 -> 1 | Y16: =T16+W16 -> 100 | Z16: =sum(G16:H16) -> 30 | AA16: =sum(G16:H16) -> 30 | AB16: 0 | AC16: 0 | AD16: 0 | AE16: 0 | AF16: 0 | AG16: 0
A17: 14 | B17: 3 | C17: 0 | D17: 0 | E17: 0 | F17: 0 | G17: 12 | H17: 18 | I17: 0 | J17: 0 | K17: 223 | L17: 0 | M17: 0 | N17: 0 | O17: 0 | P17: 0 | Q17: 0 | R17: 0 | S17: 0 | T17: 0 | U17: 0 | V17: 0 | W17: 0 | X17: =S17+V17 -> 0 | Y17: =T17+W17 -> 0 | Z17: =sum(G17:H17) -> 30 | AA17: =sum(G17:H17) -> 30 | AB17: 0 | AC17: 0 | AD17: 0 | AE17: 0 | AF17: 0 | AG17: 0
A18: 15 | B18: 3 | C18: 0 | D18: 0 | E18: 0 | F18: 0 | G18: 49 | H18: 36 | I18: 0 | J18: 0 | K18: 706 | L18: 0 | M18: 0 | N18: 0 | O18: 0 | P18: 0 | Q18: 0 | R18: 0 | S18: 0 | T18: 0 | U18: 0 | V18: 0 | W18: 0 | X18: =S18+V18 -> 0 | Y18: =T18+W18 -> 0 | Z18: =sum(G18:H18) -> 85 | AA18: =sum(G18:H18) -> 85 | AB18: 0 | AC18: 0 | AD18: 0 | AE18: 0 | AF18: 0 | AG18: 0
A19: 16 | B19: 3 | C19: 0 | D19: 2 | E19: 0 | F19: 0 | G19: 0 | H19: 0 | I19: 0 | J19: 0 | K19: 0 | L19: 0 | M19: 0 | N19: 0 | O19: 0 | P19: 0 | Q19: 0 | R19: 0 | S19: 0 | T19: 0 | U19: 0 | V19: 0 | W19: 0 | X19: =S19+V19 -> 0 | Y19: =T19+W19 -> 0 | Z19: =sum(G19:H19) -> 0 | AA19: =sum(G19:H19) -> 0 | AB19: 0 | AC19: 0 | AD19: 0 | AE19: 0 | AF19: 0 | AG19: 0 | AH19: 01 cháy cỏ (CC) 01 cháy điện (KCC)
A20: 17 | B20: 3 | C20: 0 | D20: 0 | E20: 0 | F20: 0 | G20: 3 | H20: 0 | I20: 1 | J20: 0 | K20: 17 | L20: 1 | M20: 1 | N20: 50 | O20: 0 | P20: 0 | Q20: 0 | R20: 0 | S20: 0 | T20: 0 | U20: 0 | V20: 0 | W20: 0 | X20: =S20+V20 -> 0 | Y20: =T20+W20 -> 0 | Z20: =sum(G20:H20) -> 3 | AA20: =sum(G20:H20) -> 3 | AB20: 0 | AC20: 0 | AD20: 0 | AE20: 0 | AF20: 0 | AG20: 0
A21: 18 | B21: 3 | C21: 0 | D21: 0 | E21: 0 | F21: 0 | G21: 2 | H21: 0 | I21: 1 | J21: 0 | K21: 11 | L21: 1 | M21: 1 | N21: 50 | O21: 0 | P21: 0 | Q21: 0 | R21: 0 | S21: 0 | T21: 0 | U21: 0 | V21: 0 | W21: 0 | X21: =S21+V21 -> 0 | Y21: =T21+W21 -> 0 | Z21: =sum(G21:H21) -> 2 | AA21: =sum(G21:H21) -> 2 | AB21: 0 | AC21: 0 | AD21: 0 | AE21: 0 | AF21: 0 | AG21: 0
A22: 19 | B22: 3 | C22: 0 | D22: 1 | E22: 0 | F22: 0 | G22: 2 | H22: 1 | I22: 0 | J22: 0 | K22: 17 | L22: 0 | M22: 0 | N22: 0 | O22: 0 | P22: 0 | Q22: 0 | R22: 0 | S22: 0 | T22: 0 | U22: 0 | V22: 2 | W22: 76 | X22: =S22+V22 -> 2 | Y22: =T22+W22 -> 76 | Z22: =sum(G22:H22) -> 3 | AA22: =sum(G22:H22) -> 3 | AB22: 0 | AC22: 0 | AD22: 0 | AE22: 0 | AF22: 0 | AG22: 0 | AH22: 01 cháy cỏ (CC)
A23: 20 | B23: 3 | C23: 0 | D23: 0 | E23: 0 | F23: 0 | G23: 1 | H23: 3 | I23: 0 | J23: 0 | K23: 24 | L23: 0 | M23: 0 | N23: 0 | O23: 0 | P23: 0 | Q23: 0 | R23: 0 | S23: 0 | T23: 0 | U23: 0 | V23: 1 | W23: 25 | X23: =S23+V23 -> 1 | Y23: =T23+W23 -> 25 | Z23: =sum(G23:H23) -> 4 | AA23: =sum(G23:H23) -> 4 | AB23: 0 | AC23: 0 | AD23: 0 | AE23: 0 | AF23: 0 | AG23: 0
A24: 21 | B24: 3 | C24: 0 | D24: 0 | E24: 0 | F24: 1 | G24: 3 | H24: 3 | I24: 0 | J24: 0 | K24: 39 | L24: 0 | M24: 0 | N24: 0 | O24: 0 | P24: 0 | Q24: 0 | R24: 0 | S24: 0 | T24: 0 | U24: 0 | V24: 3 | W24: 140 | X24: =S24+V24 -> 3 | Y24: =T24+W24 -> 140 | Z24: =sum(G24:H24) -> 6 | AA24: =sum(G24:H24) -> 6 | AB24: 2 | AC24: 2 | AD24: 0 | AE24: 0 | AF24: 0 | AG24: 0
A25: 22 | B25: 3 | C25: 0 | D25: 1 | E25: 0 | F25: 0 | G25: 0 | H25: 0 | I25: 0 | J25: 0 | K25: 0 | L25: 0 | M25: 0 | N25: 0 | O25: 0 | P25: 0 | Q25: 0 | R25: 0 | S25: 2 | T25: 389 | U25: 389 | V25: 4 | W25: 140 | X25: =S25+V25 -> 6 | Y25: =T25+W25 -> 529 | Z25: =sum(G25:H25) -> 0 | AA25: =sum(G25:H25) -> 0 | AB25: 2 | AC25: 2 | AD25: 0 | AE25: 0 | AF25: 0 | AG25: 0 | AH25: 01 cháy điện (KCC)
A26: 23 | B26: 3 | C26: 0 | D26: 1 | E26: 0 | F26: 0 | G26: 0 | H26: 0 | I26: 0 | J26: 0 | K26: 0 | L26: 0 | M26: 0 | N26: 0 | O26: 0 | P26: 0 | Q26: 0 | R26: 0 | S26: 1 | T26: 300 | U26: 300 | V26: 2 | W26: 115 | X26: =S26+V26 -> 3 | Y26: =T26+W26 -> 415 | Z26: 0 | AA26: 0 | AB26: 1 | AC26: 1 | AD26: 0 | AE26: 0 | AF26: 0 | AG26: 0 | AH26: 01 cháy do chập điện (KCC)
A27: 24 | B27: 3 | C27: 0 | D27: 0 | E27: 0 | F27: 0 | G27: 3 | H27: 1 | I27: 0 | J27: 0 | K27: 22 | L27: 0 | M27: 0 | N27: 0 | O27: 0 | P27: 0 | Q27: 1 | R27: 0 | S27: 0 | T27: 0 | U27: 0 | V27: 0 | W27: 0 | X27: =S27+V27 -> 0 | Y27: =T27+W27 -> 0 | Z27: =sum(G27:H27) -> 4 | AA27: =sum(G27:H27) -> 4 | AB27: 0 | AC27: 0 | AD27: 0 | AE27: 0 | AF27: 0 | AG27: 0
A28: 25 | B28: 3 | C28: 1 | D28: 1 | E28: 0 | F28: 0 | G28: 4 | H28: 4 | I28: 0 | J28: 0 | K28: 53 | L28: 0 | M28: 0 | N28: 0 | O28: 0 | P28: 0 | Q28: 0 | R28: 0 | S28: 0 | T28: 0 | U28: 0 | V28: 2 | W28: 100 | X28: =S28+V28 -> 2 | Y28: =T28+W28 -> 100 | Z28: =sum(G28:H28) -> 8 | AA28: =sum(G28:H28) -> 8 | AB28: 0 | AC28: 0 | AD28: 0 | AE28: 0 | AF28: 0 | AG28: 0 | AH28: 01 cháy Công ty (CC) 01 cháy cỏ (CC)
A29: 26 | B29: 3 | C29: 0 | D29: 0 | E29: 0 | F29: 0 | G29: 6 | H29: 0 | I29: 0 | J29: 0 | K29: 38 | L29: 0 | M29: 0 | N29: 0 | O29: 0 | P29: 0 | Q29: 0 | R29: 0 | S29: 0 | T29: 0 | U29: 0 | V29: 0 | W29: 0 | X29: =S29+V29 -> 0 | Y29: =T29+W29 -> 0 | Z29: =sum(G29:H29) -> 6 | AA29: =sum(G29:H29) -> 6 | AB29: 0 | AC29: 0 | AD29: 0 | AE29: 0 | AF29: 0 | AG29: 0
A30: 27 | B30: 3 | C30: 0 | D30: 1 | E30: 0 | F30: 0 | G30: 3 | H30: 7 | I30: 0 | J30: 0 | K30: 57 | L30: 0 | M30: 0 | N30: 0 | O30: 0 | P30: 0 | Q30: 0 | R30: 0 | S30: 0 | T30: 0 | U30: 0 | V30: 0 | W30: 0 | X30: =S30+V30 -> 0 | Y30: =T30+W30 -> 0 | Z30: =sum(G30:H30) -> 10 | AA30: =sum(G30:H30) -> 10 | AB30: 1 | AC30: 1 | AD30: 0 | AE30: 0 | AF30: 0 | AG30: 0 | AH30: 01 cháy cỏ (CC)
A31: 28 | B31: 3 | C31: 0 | D31: 1 | E31: 0 | F31: 0 | G31: 2 | H31: 7 | I31: 0 | J31: 0 | K31: 52 | L31: 0 | M31: 0 | N31: 0 | O31: 0 | P31: 0 | Q31: 0 | R31: 0 | S31: 0 | T31: 0 | U31: 0 | V31: 2 | W31: 185 | X31: =S31+V31 -> 2 | Y31: =T31+W31 -> 185 | Z31: =sum(G31:H31) -> 9 | AA31: =sum(G31:H31) -> 9 | AB31: 0 | AC31: 0 | AD31: 0 | AE31: 0 | AF31: 0 | AG31: 0 | AH31: 01 cháy cỏ (CC)
A32: 29 | B32: 3 | C32: 0 | D32: 4 | E32: 0 | F32: 0 | G32: 0 | H32: 0 | I32: 0 | J32: 0 | K32: 0 | L32: 0 | M32: 0 | N32: 0 | O32: 0 | P32: 0 | Q32: 0 | R32: 0 | S32: 0 | T32: 0 | U32: 0 | V32: 1 | W32: 56 | X32: =S32+V32 -> 1 | Y32: =T32+W32 -> 56 | Z32: =sum(G32:H32) -> 0 | AA32: =sum(G32:H32) -> 0 | AB32: 1 | AC32: 1 | AD32: 0 | AE32: 0 | AF32: 0 | AG32: 0 | AH32: 01 cháy cỏ 01 cháy điện 01 cháy nhà 01 VV ANTT
A33: 30 | B33: 3 | C33: 0 | D33: 1 | E33: 0 | F33: 0 | G33: 0 | H33: 0 | I33: 0 | J33: 0 | K33: 0 | L33: 0 | M33: 0 | N33: 0 | O33: 0 | P33: 0 | Q33: 0 | R33: 0 | S33: 0 | T33: 0 | U33: 0 | V33: 0 | W33: 0 | X33: =S33+V33 -> 0 | Y33: =T33+W33 -> 0 | Z33: =sum(G33:H33) -> 0 | AA33: =sum(G33:H33) -> 0 | AB33: 0 | AC33: 0 | AD33: 0 | AE33: 0 | AF33: 0 | AG33: 0 | AH33: 01 cháy cỏ
A34: 31 | B34: 3 | C34: 0 | D34: 1 | E34: 1 | F34: 0 | G34: 2 | H34: 1 | I34: 0 | J34: 0 | K34: 12 | L34: 1 | M34: 1 | N34: 25 | O34: 0 | P34: 0 | Q34: 0 | R34: 0 | S34: 0 | T34: 0 | U34: 0 | V34: 1 | W34: 30 | X34: =S34+V34 -> 1 | Y34: =T34+W34 -> 30 | Z34: =sum(G34:H34) -> 3 | AA34: =sum(G34:H34) -> 3 | AB34: 1 | AC34: 1 | AD34: 0 | AE34: 0 | AF34: 0 | AG34: 0 | AH34: 01 vụ cháy cỏ (KCC)
A35: 1 | B35: 4 | C35: 0 | D35: 1 | E35: 0 | F35: 0 | G35: 1 | H35: 8 | I35: 0 | J35: 1 | K35: 62 | L35: 1 | M35: 1 | N35: 50 | O35: 0 | P35: 0 | Q35: 0 | R35: 0 | S35: 0 | T35: 0 | U35: 0 | V35: 1 | W35: 25 | X35: =S35+V35 -> 1 | Y35: =T35+W35 -> 25 | Z35: =sum(G35:H35) -> 9 | AA35: =sum(G35:H35) -> 9 | AB35: 1 | AC35: 1 | AD35: 0 | AE35: 0 | AF35: 0 | AG35: 0 | AH35: 01 vụ cháy cỏ (CC)
A36: 2 | B36: 4 | C36: 0 | D36: 0 | E36: 0 | F36: 0 | G36: 4 | H36: 3 | I36: 0 | J36: 0 | K36: 42 | L36: 0 | M36: 0 | N36: 0 | O36: 0 | P36: 0 | Q36: 0 | R36: 0 | S36: 0 | T36: 0 | U36: 0 | V36: 0 | W36: 0 | X36: =S36+V36 -> 0 | Y36: =T36+W36 -> 0 | Z36: =sum(G36:H36) -> 7 | AA36: =sum(G36:H36) -> 7 | AB36: 0 | AC36: 0 | AD36: 0 | AE36: 0 | AF36: 0 | AG36: 0
A37: 3 | B37: 4 | C37: 0 | D37: 2 | E37: 0 | F37: 0 | G37: 10 | H37: 1 | I37: 0 | J37: 1 | K37: 76 | L37: 1 | M37: 1 | N37: 50 | O37: 0 | P37: 0 | Q37: 0 | R37: 0 | S37: 0 | T37: 0 | U37: 0 | V37: 0 | W37: 0 | X37: =S37+V37 -> 0 | Y37: =T37+W37 -> 0 | Z37: =sum(G37:H37) -> 11 | AA37: =sum(G37:H37) -> 11 | AB37: 0 | AC37: 0 | AD37: 0 | AE37: 0 | AF37: 0 | AG37: 0 | AH37: 02 vụ cháy cỏ (CC)
A38: 4 | B38: 4 | C38: 0 | D38: 2 | E38: 0 | F38: 0 | G38: 2 | H38: 4 | I38: 0 | J38: 0 | K38: 40 | L38: 0 | M38: 0 | N38: 0 | O38: 0 | P38: 0 | Q38: 0 | R38: 0 | S38: 0 | T38: 0 | U38: 0 | V38: 1 | W38: 28 | X38: =S38+V38 -> 1 | Y38: =T38+W38 -> 28 | Z38: =sum(G38:H38) -> 6 | AA38: =sum(G38:H38) -> 6 | AB38: 2 | AC38: 2 | AD38: 0 | AE38: 0 | AF38: 0 | AG38: 0 | AH38: 02 vụ cháy cỏ (CC)
A39: 5 | B39: 4 | C39: 0 | D39: 1 | E39: 0 | F39: 0 | G39: 5 | H39: 3 | I39: 0 | J39: 0 | K39: 53 | L39: 0 | M39: 0 | N39: 0 | O39: 0 | P39: 0 | Q39: 0 | R39: 0 | S39: 0 | T39: 0 | U39: 0 | V39: 2 | W39: 105 | X39: =S39+V39 -> 2 | Y39: =T39+W39 -> 105 | Z39: =sum(G39:H39) -> 8 | AA39: =sum(G39:H39) -> 8 | AB39: 0 | AC39: 0 | AD39: 0 | AE39: 0 | AF39: 0 | AG39: 0 | AH39: 01 cháy bãi rác (CC)
A40: 6 | B40: 4 | C40: 0 | D40: 0 | E40: 0 | F40: 0 | G40: 0 | H40: 0 | I40: 0 | J40: 0 | K40: 0 | L40: 0 | M40: 0 | N40: 0 | O40: 0 | P40: 0 | Q40: 0 | R40: 0 | S40: 0 | T40: 0 | U40: 0 | V40: 0 | W40: 0 | X40: =S40+V40 -> 0 | Y40: =T40+W40 -> 0 | Z40: =sum(G40:H40) -> 0 | AA40: =sum(G40:H40) -> 0 | AB40: 0 | AC40: 0 | AD40: 0 | AE40: 0 | AF40: 0 | AG40: 0
...

Sheet BC TUẦN
A1: NGÀY | B1: THÁNG | C1: VỤ CHÁY VÀ CNCH | G1: CÔNG TÁC KIỂM TRA | Q1: TUYÊN TRUYỀN PCCC | V1: HUẤN LUYỆN PCCC | X1: TỔNG TUYÊN TRUYỀN/HUẤN LUYỆN | Z1: PACC&CNCH của cơ sở theo mẫu PC06 | AB1: PACC&CNCH của CQ CA theo mẫu PC08 | AD1: PA CNCH của CQ CA theo mẫu PC09 | AF1: PACC&CNCH của phương tiện giao thông theo mẫu PC07
C2: VỤ CHÁY THỐNG KÊ | D2: SCLQ ĐẾN PCCC& CNCH | E2: CHI VIỆN | F2: CNCH | G2: ĐỊNH KỲ | I2: ĐỘT XUẤT | K2: HƯỚNG DẪN | L2: KIẾN NGHỊ | M2: XỬ PHẠT | N2: TIỀN PHẠT (triệu đồng) | O2: ĐÌNH CHỈ | P2: PHỤC HỒI | Q2: TIN BÀI | R2: PHÓNG SỰ | S2: SỐ LỚP TUYÊN TRUYỀN | T2: SỐ NGƯỜI THAM DỰ | U2: SỐ KHUYẾN CÁO, TỜ RƠI ĐÃ PHÁT | V2: SỐ LỚP HUẤN LUYỆN | W2: SỐ NGƯỜI THAM DỰ | X2: SỐ LỚP | Y2: SỐ NGƯỜI THAM DỰ | Z2: SỐ PA XÂY DỰNG VÀ PHÊ DUYỆT | AA2: SỐ PA ĐƯỢC THỰC TẬP | AB2: SỐ PA XÂY DỰNG VÀ PHÊ DUYỆT | AC2: SỐ PA ĐƯỢC THỰC TẬP | AD2: SỐ PA XÂY DỰNG VÀ PHÊ DUYỆT | AE2: SỐ PA ĐƯỢC THỰC TẬP | AF2: SỐ PA XÂY DỰNG VÀ PHÊ DUYỆT | AG2: SỐ PA ĐƯỢC THỰC TẬP
G3: NHÓM I | H3: NHÓM II | I3: NHÓM I | J3: NHÓM II
A4: 26/02-04/03/2026 | B4: 2 - 3 | C4: =SUM('BC NGÀY 1'!C106:C108)+SUM('BC NGÀY'!C4:C7) -> 0 | D4: =SUM('BC NGÀY 1'!D106:D108)+SUM('BC NGÀY'!D4:D7) -> 2 | E4: =SUM('BC NGÀY 1'!E106:E108)+SUM('BC NGÀY'!E4:E7) -> 0 | F4: =SUM('BC NGÀY 1'!F106:F108)+SUM('BC NGÀY'!F4:F7) -> 2 | G4: =SUM('BC NGÀY 1'!G106:G108)+SUM('BC NGÀY'!G4:G7) -> 19 | H4: =SUM('BC NGÀY 1'!H106:H108)+SUM('BC NGÀY'!H4:H7) -> 4 | I4: =SUM('BC NGÀY 1'!I106:I108)+SUM('BC NGÀY'!I4:I7) -> 0 | J4: =SUM('BC NGÀY 1'!J106:J108)+SUM('BC NGÀY'!J4:J7) -> 0 | ... AG4: =SUM('BC NGÀY 1'!AG106:AG108)+SUM('BC NGÀY'!AG4:AG7) -> 0
A5: 05/03-11/03/2926 | B5: 3 | C5: =sum('BC NGÀY'!C8:C14) -> 0 | D5: =sum('BC NGÀY'!D8:D14) -> 0 | E5: =sum('BC NGÀY'!E8:E14) -> 0 | F5: =sum('BC NGÀY'!F8:F14) -> 0 | G5: =sum('BC NGÀY'!G8:G14) -> 104 | H5: =sum('BC NGÀY'!H8:H14) -> 68 | I5: =sum('BC NGÀY'!I8:I14) -> 0 | J5: =sum('BC NGÀY'!J8:J14) -> 0 | ... AG5: =sum('BC NGÀY'!AG8:AG14) -> 0
A6: 12/03-18/03/2026 | B6: 3 | C6: =sum('BC NGÀY'!C15:C21) -> 0 | D6: =sum('BC NGÀY'!D15:D21) -> 2 | E6: =sum('BC NGÀY'!E15:E21) -> 0 | F6: =sum('BC NGÀY'!F15:F21) -> 0 | G6: =sum('BC NGÀY'!G15:G21) -> 110 | H6: =sum('BC NGÀY'!H15:H21) -> 83 | I6: =sum('BC NGÀY'!I15:I21) -> 2 | J6: =sum('BC NGÀY'!J15:J21) -> 0 | ... AG6: =sum('BC NGÀY'!AG15:AG21) -> 0
A7: 19/3-25/3/2026 | B7: 3 | C7: =sum('BC NGÀY'!C22:C28) -> 1 | D7: =sum('BC NGÀY'!D22:D28) -> 4 | E7: =sum('BC NGÀY'!E22:E28) -> 0 | F7: =sum('BC NGÀY'!F22:F28) -> 1 | G7: =sum('BC NGÀY'!G22:G28) -> 13 | H7: =sum('BC NGÀY'!H22:H28) -> 12 | I7: =sum('BC NGÀY'!I22:I28) -> 0 | J7: =sum('BC NGÀY'!J22:J28) -> 0 | ... AG7: =sum('BC NGÀY'!AG22:AG28) -> 0
A8: 26/3-01/4/2026 | B8: 3 | C8: =sum('BC NGÀY'!C29:C35) -> 0 | D8: =sum('BC NGÀY'!D29:D35) -> 9 | E8: =sum('BC NGÀY'!E29:E35) -> 1 | F8: =sum('BC NGÀY'!F29:F35) -> 0 | G8: =sum('BC NGÀY'!G29:G35) -> 14 | H8: =sum('BC NGÀY'!H29:H35) -> 23 | I8: =sum('BC NGÀY'!I29:I35) -> 0 | J8: =sum('BC NGÀY'!J29:J35) -> 1 | ... AD8: =sum('BC NGÀY'!AD29:AD35) -> 0 | AE8: =sum('BC NGÀY'!AE29:AE34) -> 0 | AF8: =sum('BC NGÀY'!AF29:AF34) -> 0 | AG8: =sum('BC NGÀY'!AG29:AG34) -> 0
A9: 02/4-08/4/2026 | B9: 4 | C9: =sum('BC NGÀY'!C36:C42) -> 0 | D9: =sum('BC NGÀY'!D36:D42) -> 6 | E9: =sum('BC NGÀY'!E36:E42) -> 0 | F9: =sum('BC NGÀY'!F36:F42) -> 0 | G9: =sum('BC NGÀY'!G36:G42) -> 34 | H9: =sum('BC NGÀY'!H36:H42) -> 24 | I9: =sum('BC NGÀY'!I36:I42) -> 0 | J9: =sum('BC NGÀY'!J36:J42) -> 1 | ... AG9: =sum('BC NGÀY'!AG36:AG42) -> 0
A10: 09/4-15/4/2026 | B10: 4 | C10: =sum('BC NGÀY'!C43:C49) -> 0 | D10: =sum('BC NGÀY'!D43:D49) -> 6 | E10: =sum('BC NGÀY'!E43:E49) -> 1 | F10: =sum('BC NGÀY'!F43:F49) -> 1 | G10: =sum('BC NGÀY'!G43:G49) -> 43 | H10: =sum('BC NGÀY'!H43:H49) -> 23 | I10: =sum('BC NGÀY'!I43:I49) -> 0 | J10: =sum('BC NGÀY'!J43:J49) -> 1 | ... AG10: =sum('BC NGÀY'!AG43:AG49) -> 0
A11: 16/4-22/4/2026 | B11: 4 | C11: =sum('BC NGÀY'!C50:C56) -> 0 | D11: =sum('BC NGÀY'!D50:D56) -> 9 | E11: =sum('BC NGÀY'!E50:E56) -> 0 | F11: =sum('BC NGÀY'!F50:F56) -> 0 | G11: =sum('BC NGÀY'!G50:G56) -> 20 | H11: =sum('BC NGÀY'!H50:H56) -> 10 | I11: =sum('BC NGÀY'!I50:I56) -> 5 | J11: =sum('BC NGÀY'!J50:J56) -> 7 | ... AG11: =sum('BC NGÀY'!AG50:AG56) -> 0
A12: 23/4-29/4/2026 | B12: 4 | C12: =sum('BC NGÀY'!C57:C63) -> 0 | D12: =sum('BC NGÀY'!D57:D63) -> 5 | E12: =sum('BC NGÀY'!E57:E63) -> 0 | F12: =sum('BC NGÀY'!F57:F63) -> 0 | G12: =sum('BC NGÀY'!G57:G63) -> 14 | H12: =sum('BC NGÀY'!H57:H63) -> 24 | I12: =sum('BC NGÀY'!I57:I63) -> 6 | J12: =sum('BC NGÀY'!J57:J63) -> 6 | ... AG12: =sum('BC NGÀY'!AG57:AG63) -> 0

Sheet BC THÁNG
A1: THÁNG | B1: VỤ CHÁY VÀ CNCH | F1: CÔNG TÁC KIỂM TRA | P1: TUYÊN TRUYỀN PCCC | U1: HUẤN LUYỆN PCCC | W1: TỔNG TUYÊN TRUYỀN/HUẤN LUYỆN | Y1: PACC&CNCH của cơ sở theo mẫu PC06 | AA1: PACC&CNCH của CQ CA theo mẫu PC08 | AC1: PA CNCH của CQ CA theo mẫu PC09 | AE1: PACC&CNCH của phương tiện giao thông theo mẫu PC07
B2: VỤ CHÁY THỐNG KÊ | C2: SCLQ ĐẾN PCCC& CNCH | D2: CHI VIỆN | E2: CNCH | F2: ĐỊNH KỲ | H2: ĐỘT XUẤT | J2: HƯỚNG DẪN | K2: KIẾN NGHỊ | L2: XỬ PHẠT | M2: TIỀN PHẠT (triệu đồng) | N2: ĐÌNH CHỈ | O2: PHỤC HỒI | P2: TIN BÀI | Q2: PHÓNG SỰ | R2: SỐ LỚP TUYÊN TRUYỀN | S2: SỐ NGƯỜI THAM DỰ | T2: SỐ KHUYẾN CÁO, TỜ RƠI ĐÃ PHÁT | U2: SỐ LỚP HUẤN LUYỆN | V2: SỐ NGƯỜI THAM DỰ | W2: SỐ LỚP | X2: SỐ NGƯỜI THAM DỰ | Y2: SỐ PA XÂY DỰNG VÀ PHÊ DUYỆT | Z2: SỐ PA ĐƯỢC THỰC TẬP | AA2: SỐ PA XÂY DỰNG VÀ PHÊ DUYỆT | AB2: SỐ PA ĐƯỢC THỰC TẬP | AC2: SỐ PA XÂY DỰNG VÀ PHÊ DUYỆT | AD2: SỐ PA ĐƯỢC THỰC TẬP | AE2: SỐ PA XÂY DỰNG VÀ PHÊ DUYỆT | AF2: SỐ PA ĐƯỢC THỰC TẬP
F3: NHÓM I | G3: NHÓM II | H3: NHÓM I | I3: NHÓM II
A4: Thống kê T2 (14 - 28/02/26) | B4: 1 | C4: 11 | D4: 0 | E4: 0 | F4: 0 | G4: 2 | H4: 0 | I4: 0 | J4: 8 | K4: 0 | L4: 0 | M4: 0 | N4: 0 | O4: 0 | P4: 0 | Q4: 0 | R4: 1 | S4: 258 | T4: 258 | U4: 0 | V4: 0 | W4: =R4+U4 -> 1 | X4: =S4+V4 -> 258 | Y4: 2 | Z4: 2 | AA4: 0 | AB4: 0 | AC4: 0 | AD4: 0 | AE4: 0 | AF4: 0
A5: Thống kê T3 (01 - 14/03/26) | B5: =sum('BC NGÀY'!C4:C16) -> 0 | C5: =sum('BC NGÀY'!D4:D16) -> 0 | D5: =sum('BC NGÀY'!E4:E16) -> 0 | E5: =sum('BC NGÀY'!F4:F16) -> 2 | F5: =sum('BC NGÀY'!G4:G16) -> 167 | G5: =sum('BC NGÀY'!H4:H16) -> 101 | H5: =sum('BC NGÀY'!I4:I16) -> 0 | I5: =sum('BC NGÀY'!J4:J16) -> 0 | ... AF5: =sum('BC NGÀY'!AG4:AG16) -> 0
A6: T3 | B6: =SUM(B4:B5) -> 1 | C6: =SUM(C4:C5) -> 11 | D6: =SUM(D4:D5) -> 0 | E6: =SUM(E4:E5) -> 2 | F6: =SUM(F4:F5) -> 167 | G6: =SUM(G4:G5) -> 103 | H6: =SUM(H4:H5) -> 0 | I6: =SUM(I4:I5) -> 0 | ... O6: =SUM(O4:O5) -> 0 | P6: 10 | Q6: =SUM(Q4:Q5) -> 0 | R6: =SUM(R4:R5) -> 3 | S6: =SUM(S4:S5) -> 1033 | T6: =SUM(T4:T5) -> 1033 | U6: =SUM(U4:U5) -> 4 | V6: =SUM(V4:V5) -> 170 | W6: =SUM(W4:W5) -> 7 | X6: =SUM(X4:X5) -> 1203 | ... AF6: =SUM(AF4:AF5) -> 0
A7: T4 | B7: =sum('BC NGÀY'!C17:C47) -> 1 | C7: =sum('BC NGÀY'!D17:D47) -> 26 | D7: =sum('BC NGÀY'!E17:E47) -> 2 | E7: =sum('BC NGÀY'!F17:F47) -> 2 | F7: =sum('BC NGÀY'!G17:G47) -> 159 | G7: =sum('BC NGÀY'!H17:H47) -> 131 | H7: =sum('BC NGÀY'!I17:I47) -> 2 | I7: =sum('BC NGÀY'!J17:J47) -> 2 | ... AF7: =sum('BC NGÀY'!AG17:AG47) -> 0

Sheet BC QUÝ
A1: QUÝ | B1: VỤ CHÁY VÀ CNCH | F1: CÔNG TÁC KIỂM TRA | P1: TUYÊN TRUYỀN PCCC | U1: HUẤN LUYỆN PCCC | W1: TỔNG TUYÊN TRUYỀN/HUẤN LUYỆN | Y1: PACC&CNCH của cơ sở theo mẫu PC06 | AA1: PACC&CNCH của CQ CA theo mẫu PC08 | AC1: PA CNCH của CQ CA theo mẫu PC09 | AE1: PACC&CNCH của phương tiện giao thông theo mẫu PC07
B2: VỤ CHÁY THỐNG KÊ | C2: SCLQ ĐẾN PCCC& CNCH | D2: CHI VIỆN | E2: CNCH | F2: ĐỊNH KỲ | H2: ĐỘT XUẤT | J2: HƯỚNG DẪN | K2: KIẾN NGHỊ | L2: XỬ PHẠT | M2: TIỀN PHẠT (triệu đồng) | N2: ĐÌNH CHỈ | O2: PHỤC HỒI | P2: TIN BÀI | Q2: PHÓNG SỰ | R2: SỐ LỚP TUYÊN TRUYỀN | S2: SỐ NGƯỜI THAM DỰ | T2: SỐ KHUYẾN CÁO, TỜ RƠI ĐÃ PHÁT | U2: SỐ LỚP HUẤN LUYỆN | V2: SỐ NGƯỜI THAM DỰ | W2: SỐ LỚP | X2: SỐ NGƯỜI THAM DỰ | Y2: SỐ PA XÂY DỰNG VÀ PHÊ DUYỆT | Z2: SỐ PA ĐƯỢC THỰC TẬP | AA2: SỐ PA XÂY DỰNG VÀ PHÊ DUYỆT | AB2: SỐ PA ĐƯỢC THỰC TẬP | AC2: SỐ PA XÂY DỰNG VÀ PHÊ DUYỆT | AD2: SỐ PA ĐƯỢC THỰC TẬP | AE2: SỐ PA XÂY DỰNG VÀ PHÊ DUYỆT | AF2: SỐ PA ĐƯỢC THỰC TẬP
F3: NHÓM I | G3: NHÓM II | H3: NHÓM I | I3: NHÓM II
A4: T1 | B4: =SUM('BC NGÀY 1'!C33:C63) -> 0 | C4: =SUM('BC NGÀY 1'!D33:D63) -> 15 | D4: =SUM('BC NGÀY 1'!E33:E63) -> 2 | E4: =SUM('BC NGÀY 1'!F33:F63) -> 2 | F4: =SUM('BC NGÀY 1'!G33:G63) -> 115 | G4: =SUM('BC NGÀY 1'!H33:H63) -> 51 | H4: =SUM('BC NGÀY 1'!I33:I63) -> 2 | J4: 1087 | K4: 5 | L4: 5 | M4: 112 | N4: =SUM('BC NGÀY 1'!O33:O63) -> 0 | O4: 2 | P4: 7 | Q4: 4 | R4: 23 | S4: 5863 | T4: 6200 | U4: 104 | V4: 4331 | W4: 127 | X4: 10194 | Y4: 147 | Z4: 147 | AA4: 18 | AB4: 18 | AC4: 0 | AD4: 0 | AE4: 0 | AF4: 0
A5: T2 | B5: =SUM('BC NGÀY 1'!C64:C93) -> 2 | C5: =SUM('BC NGÀY 1'!D64:D93) -> 39 | D5: =SUM('BC NGÀY 1'!E64:E93) -> 1 | E5: =SUM('BC NGÀY 1'!F64:F93) -> 1 | F5: =SUM('BC NGÀY 1'!G64:G93) -> 206 | G5: =SUM('BC NGÀY 1'!H64:H93) -> 75 | H5: =SUM('BC NGÀY 1'!I64:I93) -> 4 | J5: 2012 | K5: 11 | L5: 11 | M5: 170 | N5: =SUM('BC NGÀY 1'!O64:O93) -> 0 | O5: =SUM('BC NGÀY 1'!P64:P93) -> 7 | P5: 6 | Q5: 1 | R5: 13 | S5: 5915 | T5: 5915 | U5: 57 | V5: 2748 | W5: 70 | X5: 8663 | Y5: 277 | Z5: 277 | AA5: 24 | AB5: 24 | AC5: 0 | AD5: 0 | AE5: 0 | AF5: 0
A6: T3 | B6: 1 | C6: 11 | D6: 0 | E6: 2 | F6: 167 | G6: 103 | H6: 0 | I6: 0 | J6: 2078 | K6: 0 | L6: 0 | M6: 0 | N6: 0 | O6: 0 | P6: 10 | Q6: 0 | R6: 3 | S6: 1033 | T6: 1033 | U6: 4 | V6: 170 | W6: 7 | X6: 1203 | Y6: 270 | Z6: 270 | AA6: 3 | AB6: 3 | AC6: 0 | AD6: 0 | AE6: 0 | AF6: 0
A7: Quý I | B7: =sum(B4:B6) -> 3 | C7: =sum(C4:C6) -> 65 | D7: =sum(D4:D6) -> 3 | E7: =sum(E4:E6) -> 5 | F7: =sum(F4:F6) -> 488 | G7: =sum(G4:G6) -> 229 | H7: =sum(H4:H6) -> 6 | I7: =sum(I4:I6) -> 0 | ... AF7: =sum(AF4:AF6) -> 0

Sheet BC TUẦN 1
A1: NGÀY | B1: THÁNG | C1: VỤ CHÁY VÀ CNCH | G1: CÔNG TÁC KIỂM TRA | P1: TUYÊN TRUYỀN PCCC | T1: HUẤN LUYỆN PCCC | V1: TỔNG TUYÊN TRUYỀN/HUẤN LUYỆN | X1: PACC&CNCH của cơ sở theo mẫu PC06 | Z1: PACC&CNCH của CQ CA theo mẫu PC08 | AB1: PA CNCH của CQ CA theo mẫu PC09 | AD1: PACC&CNCH của phương tiện giao thông theo mẫu PC07
C2: VỤ CHÁY CÓ THỐNG KÊ | D2: SỰ CỐ LIÊN QUAN ĐẾN PCCC&CNCH | E2: VỤ CHÁY CHI VIỆN | F2: CNCH | G2: NHÓM I | H2: NHÓM II | I2: ĐỘT XUẤT | J2: HƯỚNG DẪN | K2: KIẾN NGHỊ | L2: XỬ PHẠT | M2: TIỀN PHẠT (triệu đồng) | N2: ĐÌNH CHỈ | O2: PHỤC HỒI | P2: TIN BÀI, PHÓNG SỰ | Q2: SỐ LỚP TUYÊN TRUYỀN | R2: SỐ NGƯỜI THAM DỰ | S2: SỐ KHUYẾN CÁO, TỜ RƠI ĐÃ PHÁT | T2: SỐ LỚP HUẤN LUYỆN | U2: SỐ NGƯỜI THAM DỰ | V2: SỐ LỚP | W2: SỐ NGƯỜI THAM DỰ | X2: SỐ PA XÂY DỰNG VÀ PHÊ DUYỆT | Y2: SỐ PA ĐƯỢC THỰC TẬP | Z2: SỐ PA XÂY DỰNG VÀ PHÊ DUYỆT | AA2: SỐ PA ĐƯỢC THỰC TẬP | AB2: SỐ PA XÂY DỰNG VÀ PHÊ DUYỆT | AC2: SỐ PA ĐƯỢC THỰC TẬP | AD2: SỐ PA XÂY DỰNG VÀ PHÊ DUYỆT | AE2: SỐ PA ĐƯỢC THỰC TẬP
A3: 13/11-19/11/2025 | B3: 11 | C3: =sum('BC NGÀY 1'!C3:C7) -> 0 | D3: =sum('BC NGÀY 1'!D3:D7) -> 1 | E3: =sum('BC NGÀY 1'!E3:E7) -> 0 | F3: =sum('BC NGÀY 1'!F3:F7) -> 1 | G3: =sum('BC NGÀY 1'!G3:G7) -> 6 | H3: =sum('BC NGÀY 1'!H3:H7) -> 13 | I3: =sum('BC NGÀY 1'!I19:I25) -> 0 | J3: =sum('BC NGÀY 1'!J3:J7) -> 111 | K3: =sum('BC NGÀY 1'!K3:K7) -> 0 | L3: =sum('BC NGÀY 1'!L3:L7) -> 0 | M3: =sum('BC NGÀY 1'!M3:M7) -> 0 | N3: =sum('BC NGÀY 1'!N3:N7) -> 0 | O3: =sum('BC NGÀY 1'!O3:O7) -> 0 | P3: =sum('BC NGÀY 1'!P3:P7) -> 0 | Q3: =sum('BC NGÀY 1'!Q3:Q7) -> 1 | ... U3: =sum('BC NGÀY 1'!U3:U7) -> 0 | V3: =Q3+T3 -> 1 | W3: =R3+U3 -> 1200 | X3: =sum('BC NGÀY 1'!X3:X7) -> 19 | Y3: =sum('BC NGÀY 1'!Y3:Y7) -> 0 | Z3: =sum('BC NGÀY 1'!Z3:Z7) -> 0 | AA3: =sum('BC NGÀY 1'!AA3:AA7) -> 0 | AB3: =sum('BC NGÀY 1'!AB3:AB7) -> 0 | AC3: =sum('BC NGÀY 1'!AC3:AC7) -> 0 | AD3: =sum('BC NGÀY 1'!AD3:AD7) -> 0 | AE3: =sum('BC NGÀY 1'!AE3:AE7) -> 0
A4: 20/11-26/11/2025 | B4: 11 | C4: =sum('BC NGÀY 1'!C8:C14) -> 1 | D4: =sum('BC NGÀY 1'!D8:D14) -> 2 | E4: =sum('BC NGÀY 1'!E8:E14) -> 0 | F4: =sum('BC NGÀY 1'!F8:F14) -> 0 | G4: =sum('BC NGÀY 1'!G8:G14) -> 3 | H4: =sum('BC NGÀY 1'!H8:H14) -> 2 | I4: =sum('BC NGÀY 1'!I20:I26) -> 0 | J4: =sum('BC NGÀY 1'!J8:J14) -> 33 | K4: =sum('BC NGÀY 1'!K8:K14) -> 0 | L4: =sum('BC NGÀY 1'!L8:L14) -> 0 | M4: =sum('BC NGÀY 1'!M8:M14) -> 0 | N4: =sum('BC NGÀY 1'!N8:N14) -> 0 | O4: =sum('BC NGÀY 1'!O8:O14) -> 0 | P4: =sum('BC NGÀY 1'!P8:P14) -> 0 | Q4: =sum('BC NGÀY 1'!Q8:Q14) -> 0 | ... U4: =sum('BC NGÀY 1'!U8:U14) -> 0 | V4: =Q4+T4 -> 0 | W4: =R4+U4 -> 0 | X4: =sum('BC NGÀY 1'!X8:X14) -> 5 | Y4: =sum('BC NGÀY 1'!Y8:Y14) -> 0 | Z4: =sum('BC NGÀY 1'!Z8:Z14) -> 0 | AA4: =sum('BC NGÀY 1'!AA8:AA14) -> 0 | AB4: =sum('BC NGÀY 1'!AB8:AB14) -> 0 | AC4: =sum('BC NGÀY 1'!AC8:AC14) -> 0 | AD4: =sum('BC NGÀY 1'!AD8:AD14) -> 0 | AE4: =sum('BC NGÀY 1'!AE8:AE14) -> 0
A5: 27/11-03/12/2025 | B5: 12 | C5: =sum('BC NGÀY 1'!C15:C21) -> 0 | D5: =sum('BC NGÀY 1'!D15:D21) -> 0 | E5: =sum('BC NGÀY 1'!E15:E21) -> 0 | F5: =sum('BC NGÀY 1'!F15:F21) -> 0 | G5: =sum('BC NGÀY 1'!G15:G21) -> 3 | H5: =sum('BC NGÀY 1'!H15:H21) -> 20 | I5: =sum('BC NGÀY 1'!I21:I27) -> 0 | J5: =sum('BC NGÀY 1'!J15:J21) -> 156 | K5: =sum('BC NGÀY 1'!K15:K21) -> 0 | L5: =sum('BC NGÀY 1'!L15:L21) -> 0 | M5: =sum('BC NGÀY 1'!M15:M21) -> 0 | N5: =sum('BC NGÀY 1'!N15:N21) -> 0 | O5: =sum('BC NGÀY 1'!O15:O21) -> 0 | P5: =sum('BC NGÀY 1'!P15:P21) -> 1 | Q5: =sum('BC NGÀY 1'!Q15:Q21) -> 2 | ... U5: =sum('BC NGÀY 1'!U15:U21) -> 512 | V5: =Q5+T5 -> 13 | W5: =R5+U5 -> 1087 | X5: 23 | Y5: 23 | Z5: =sum('BC NGÀY 1'!Z15:Z21) -> 2 | AA5: =sum('BC NGÀY 1'!AA15:AA21) -> 2 | AB5: =sum('BC NGÀY 1'!AB15:AB21) -> 0 | AC5: =sum('BC NGÀY 1'!AC15:AC21) -> 0 | AD5: =sum('BC NGÀY 1'!AD15:AD21) -> 0 | AE5: =sum('BC NGÀY 1'!AE15:AE21) -> 0
A6: 04/12-10/12/2025 | B6: 12 | C6: =sum('BC NGÀY 1'!C22:C28) -> 0 | D6: =sum('BC NGÀY 1'!D22:D28) -> 2 | E6: =sum('BC NGÀY 1'!E22:E28) -> 1 | F6: =sum('BC NGÀY 1'!F22:F28) -> 0 | G6: =sum('BC NGÀY 1'!G22:G28) -> 10 | H6: =sum('BC NGÀY 1'!H22:H28) -> 25 | I6: =sum('BC NGÀY 1'!I22:I28) -> 1 | J6: =sum('BC NGÀY 1'!J22:J28) -> 218 | ... U6: =sum('BC NGÀY 1'!U22:U28) -> 458 | V6: =Q6+T6 -> 7 | W6: =R6+U6 -> 458 | X6: =sum('BC NGÀY 1'!X22:X28) -> 35 | Y6: =sum('BC NGÀY 1'!Y22:Y28) -> 0 | Z6: =sum('BC NGÀY 1'!Z22:Z28) -> 1 | AA6: =sum('BC NGÀY 1'!AA22:AA28) -> 1 | AB6: =sum('BC NGÀY 1'!AB22:AB28) -> 0 | AC6: =sum('BC NGÀY 1'!AC22:AC28) -> 0 | AD6: =sum('BC NGÀY 1'!AD22:AD28) -> 0 | AE6: =sum('BC NGÀY 1'!AE22:AE28) -> 0
A7: 11/12-17/12/2025 | B7: 12 | C7: =sum('BC NGÀY 1'!C29:C35) -> 0 | D7: =sum('BC NGÀY 1'!D29:D35) -> 1 | E7: =sum('BC NGÀY 1'!E29:E35) -> 0 | F7: =sum('BC NGÀY 1'!F29:F35) -> 1 | G7: =sum('BC NGÀY 1'!G29:G35) -> 20 | H7: =sum('BC NGÀY 1'!H29:H35) -> 23 | I7: =sum('BC NGÀY 1'!I29:I35) -> 0 | J7: =sum('BC NGÀY 1'!J29:J35) -> 289 | ... U7: =sum('BC NGÀY 1'!U29:U35) -> 910 | V7: =Q7+T7 -> 20 | W7: =R7+U7 -> 3010 | X7: =sum('BC NGÀY 1'!X29:X35) -> 36 | Y7: =sum('BC NGÀY 1'!Y29:Y35) -> 0 | Z7: =sum('BC NGÀY 1'!Z29:Z35) -> 4 | AA7: =sum('BC NGÀY 1'!AA29:AA35) -> 4 | AB7: =sum('BC NGÀY 1'!AB29:AB35) -> 0 | AC7: =sum('BC NGÀY 1'!AC29:AC35) -> 0 | AD7: =sum('BC NGÀY 1'!AD29:AD35) -> 0 | AE7: =sum('BC NGÀY 1'!AE29:AE35) -> 0
A8: 18/12-24/12/2025 | B8: 12 | C8: =sum('BC NGÀY 1'!C36:C42) -> 0 | D8: =sum('BC NGÀY 1'!D36:D42) -> 4 | E8: =sum('BC NGÀY 1'!E36:E42) -> 1 | F8: =sum('BC NGÀY 1'!F36:F42) -> 0 | G8: =sum('BC NGÀY 1'!G36:G42) -> 8 | H8: =sum('BC NGÀY 1'!H36:H42) -> 6 | I8: =sum('BC NGÀY 1'!I36:I42) -> 0 | J8: =sum('BC NGÀY 1'!J36:J42) -> 102 | ... U8: =sum('BC NGÀY 1'!U36:U42) -> 1295 | V8: =Q8+T8 -> 32 | W8: =R8+U8 -> 1695 | X8: =sum('BC NGÀY 1'!X36:X42) -> 9 | Y8: =sum('BC NGÀY 1'!Y36:Y42) -> 9 | Z8: =sum('BC NGÀY 1'!Z36:Z42) -> 8 | AA8: =sum('BC NGÀY 1'!AA36:AA42) -> 8 | AB8: =sum('BC NGÀY 1'!AB36:AB42) -> 0 | AC8: =sum('BC NGÀY 1'!AC36:AC42) -> 0 | AD8: =sum('BC NGÀY 1'!AD36:AD42) -> 0 | AE8: =sum('BC NGÀY 1'!AE36:AE42) -> 0
A9: 25/12- 31/12/2025 | B9: 1 | C9: =sum('BC NGÀY 1'!C43:C49) -> 0 | D9: =sum('BC NGÀY 1'!D43:D49) -> 1 | E9: =sum('BC NGÀY 1'!E43:E49) -> 0 | F9: =sum('BC NGÀY 1'!F43:F49) -> 1 | G9: =sum('BC NGÀY 1'!G43:G49) -> 12 | H9: =sum('BC NGÀY 1'!H43:H49) -> 7 | I9: =sum('BC NGÀY 1'!I43:I49) -> 0 | J9: =sum('BC NGÀY 1'!J43:J49) -> 31 | ... U9: =sum('BC NGÀY 1'!U43:U49) -> 1497 | V9: =Q9+T9 -> 49 | W9: =R9+U9 -> 4470 | X9: =sum('BC NGÀY 1'!X43:X49) -> 13 | Y9: =sum('BC NGÀY 1'!Y43:Y49) -> 13 | Z9: =sum('BC NGÀY 1'!Z43:Z49) -> 6 | AA9: =sum('BC NGÀY 1'!AA43:AA49) -> 6 | AB9: =sum('BC NGÀY 1'!AB43:AB49) -> 0 | AC9: =sum('BC NGÀY 1'!AC43:AC49) -> 0 | AD9: =sum('BC NGÀY 1'!AD43:AD49) -> 0 | AE9: =sum('BC NGÀY 1'!AE43:AE49) -> 0
A10: 01/01-07/01/2026 | B10: 1 | C10: =sum('BC NGÀY 1'!C50:C56) -> 0 | D10: =sum('BC NGÀY 1'!D50:D56) -> 3 | E10: =sum('BC NGÀY 1'!E50:E56) -> 1 | F10: =sum('BC NGÀY 1'!F50:F56) -> 0 | G10: =sum('BC NGÀY 1'!G50:G56) -> 17 | H10: =sum('BC NGÀY 1'!H50:H56) -> 7 | I10: =sum('BC NGÀY 1'!I50:I56) -> 1 | J10: =sum('BC NGÀY 1'!J50:J56) -> 175 | ... U10: =sum('BC NGÀY 1'!U50:U56) -> 753 | V10: =Q10+T10 -> 21 | W10: =R10+U10 -> 1093 | X10: =sum('BC NGÀY 1'!X50:X56) -> 24 | Y10: =sum('BC NGÀY 1'!Y50:Y56) -> 24 | Z10: =sum('BC NGÀY 1'!Z50:Z56) -> 0 | AA10: =sum('BC NGÀY 1'!AA50:AA56) -> 0 | AB10: =sum('BC NGÀY 1'!AB50:AB56) -> 0 | AC10: =sum('BC NGÀY 1'!AC50:AC56) -> 0 | AD10: =sum('BC NGÀY 1'!AD50:AD56) -> 0 | AE10: =sum('BC NGÀY 1'!AE50:AE56) -> 0
A11: 08/01-14/01/2026 | B11: 1 | C11: =sum('BC NGÀY 1'!C57:C63) -> 0 | D11: =sum('BC NGÀY 1'!D57:D63) -> 6 | E11: =sum('BC NGÀY 1'!E57:E63) -> 0 | F11: =sum('BC NGÀY 1'!F57:F63) -> 1 | G11: =sum('BC NGÀY 1'!G57:G63) -> 74 | H11: =sum('BC NGÀY 1'!H57:H63) -> 28 | I11: =sum('BC NGÀY 1'!I57:I63) -> 1 | J11: =sum('BC NGÀY 1'!J57:J63) -> 730 | ... AE11: =sum('BC NGÀY 1'!AE57:AE63) -> 0
A12: 15/01-21/01/2026 | B12: 1 | C12: =sum('BC NGÀY 1'!C64:C70) -> 1 | D12: =sum('BC NGÀY 1'!D64:D70) -> 4 | E12: =sum('BC NGÀY 1'!E64:E70) -> 0 | F12: =sum('BC NGÀY 1'!F64:F70) -> 1 | G12: =sum('BC NGÀY 1'!G64:G70) -> 70 | H12: =sum('BC NGÀY 1'!H64:H70) -> 16 | I12: =sum('BC NGÀY 1'!I64:I70) -> 0 | J12: =sum('BC NGÀY 1'!J64:J70) -> 625 | ... AE12: =sum('BC NGÀY 1'!AE64:AE70) -> 0
A13: 22/01-28/01/2026 | B13: 1 | C13: =sum('BC NGÀY 1'!C71:C77) -> 0 | D13: =sum('BC NGÀY 1'!D71:D77) -> 11 | E13: =sum('BC NGÀY 1'!E71:E77) -> 0 | F13: =sum('BC NGÀY 1'!F71:F77) -> 0 | G13: =sum('BC NGÀY 1'!G71:G77) -> 28 | H13: =sum('BC NGÀY 1'!H71:H77) -> 9 | I13: =sum('BC NGÀY 1'!I71:I77) -> 0 | J13: =sum('BC NGÀY 1'!J71:J77) -> 269 | ... AE13: =sum('BC NGÀY 1'!AE71:AE77) -> 0
A14: 29/01-04/02/2026 | B14: 46054 | C14: =sum('BC NGÀY 1'!C78:C84) -> 1 | D14: =sum('BC NGÀY 1'!D78:D84) -> 14 | E14: =sum('BC NGÀY 1'!E78:E84) -> 1 | F14: =sum('BC NGÀY 1'!F78:F84) -> 0 | G14: =sum('BC NGÀY 1'!G78:G84) -> 51 | H14: =sum('BC NGÀY 1'!H78:H84) -> 25 | I14: =sum('BC NGÀY 1'!I78:I84) -> 1 | J14: =sum('BC NGÀY 1'!J78:J84) -> 602 | ... AE14: =sum('BC NGÀY 1'!AE78:AE84) -> 0
A15: 05/02-11/02/2026 | B15: 2 | C15: =sum('BC NGÀY 1'!C85:C91) -> 0 | D15: =sum('BC NGÀY 1'!D85:D91) -> 10 | E15: =sum('BC NGÀY 1'!E85:E91) -> 0 | F15: =sum('BC NGÀY 1'!F85:F91) -> 0 | G15: =sum('BC NGÀY 1'!G85:G91) -> 56 | H15: =sum('BC NGÀY 1'!H85:H91) -> 23 | I15: =sum('BC NGÀY 1'!I85:I91) -> 3 | J15: =sum('BC NGÀY 1'!J85:J91) -> 500 | ... AE15: =sum('BC NGÀY 1'!AE85:AE91) -> 0
A16: 12/02-18/02/2026 | B16: 2 | C16: =sum('BC NGÀY 1'!C92:C98) -> 0 | D16: =sum('BC NGÀY 1'!D92:D98) -> 5 | E16: =sum('BC NGÀY 1'!E92:E98) -> 0 | F16: =sum('BC NGÀY 1'!F92:F98) -> 0 | G16: =sum('BC NGÀY 1'!G92:G98) -> 1 | H16: =sum('BC NGÀY 1'!H92:H98) -> 2 | I16: =sum('BC NGÀY 1'!I92:I98) -> 0 | J16: =sum('BC NGÀY 1'!J92:J98) -> 16 | ... AE16: =sum('BC NGÀY 1'!AE92:AE98) -> 0
A17: 19/02-25/02/2026 | B17: 2 | C17: =sum('BC NGÀY 1'!C99:C105) -> 1 | D17: =sum('BC NGÀY 1'!D99:D105) -> 4 | E17: =sum('BC NGÀY 1'!E99:E105) -> 0 | F17: =sum('BC NGÀY 1'!F99:F105) -> 0 | G17: =sum('BC NGÀY 1'!G99:G105) -> 0 | H17: =sum('BC NGÀY 1'!H99:H105) -> 2 | I17: =sum('BC NGÀY 1'!I99:I105) -> 0 | J17: =sum('BC NGÀY 1'!J99:J105) -> 8 | ... AE17: =sum('BC NGÀY 1'!AE99:AE105) -> 0

Sheet BC THÁNG 1
A1: THÁNG | B1: VỤ CHÁY VÀ CNCH | F1: CÔNG TÁC KIỂM TRA | O1: TUYÊN TRUYỀN PCCC | S1: HUẤN LUYỆN PCCC | U1: TỔNG TUYÊN TRUYỀN/HUẤN LUYỆN | W1: PACC&CNCH của cơ sở theo mẫu PC06 | Y1: PACC&CNCH của CQ CA theo mẫu PC08 | AA1: PA CNCH của CQ CA theo mẫu PC09 | AC1: PACC&CNCH của phương tiện giao thông theo mẫu PC07
B2: VỤ CHÁY CÓ THỐNG KÊ | C2: SỰ CỐ LIÊN QUAN ĐẾN PCCC&CNCH | D2: VỤ CHÁY CHI VIỆN | E2: CNCH | F2: NHÓM I | G2: NHÓM II | H2: ĐỘT XUẤT | I2: HƯỚNG DẪN | J2: KIẾN NGHỊ | K2: XỬ PHẠT | L2: TIỀN PHẠT (triệu đồng) | M2: ĐÌNH CHỈ | N2: PHỤC HỒI | O2: TIN BÀI, PHÓNG SỰ | P2: SỐ LỚP TUYÊN TRUYỀN | Q2: SỐ NGƯỜI THAM DỰ | R2: SỐ KHUYẾN CÁO, TỜ RƠI ĐÃ PHÁT | S2: SỐ LỚP HUẤN LUYỆN | T2: SỐ NGƯỜI THAM DỰ | U2: SỐ LỚP | V2: SỐ NGƯỜI THAM DỰ | W2: SỐ PA XÂY DỰNG VÀ PHÊ DUYỆT | X2: SỐ PA ĐƯỢC THỰC TẬP | Y2: SỐ PA XÂY DỰNG VÀ PHÊ DUYỆT | Z2: SỐ PA ĐƯỢC THỰC TẬP | AA2: SỐ PA XÂY DỰNG VÀ PHÊ DUYỆT | AB2: SỐ PA ĐƯỢC THỰC TẬP | AC2: SỐ PA XÂY DỰNG VÀ PHÊ DUYỆT | AD2: SỐ PA ĐƯỢC THỰC TẬP
A3: 12 | B3: =SUM('BC NGÀY 1'!C3:C31) -> 1 | C3: =SUM('BC NGÀY 1'!D3:D31) -> 5 | D3: =SUM('BC NGÀY 1'!E3:E31) -> 1 | E3: =SUM('BC NGÀY 1'!F3:F31) -> 2 | F3: =SUM('BC NGÀY 1'!G3:G31) -> 38 | G3: =SUM('BC NGÀY 1'!H3:H31) -> 80 | H3: =SUM('BC NGÀY 1'!I3:I31) -> 1 | I3: =SUM('BC NGÀY 1'!J3:J31) -> 758 | ... T3: =SUM('BC NGÀY 1'!U3:U31) -> 1395 | U3: =P3+S3 -> 31 | V3: =Q3+T3 -> 3370 | W3: =SUM('BC NGÀY 1'!X3:X31) -> 118 | X3: =SUM('BC NGÀY 1'!Y3:Y31) -> 0 | Y3: =SUM('BC NGÀY 1'!Z3:Z31) -> 4 | Z3: =SUM('BC NGÀY 1'!AA3:AA31) -> 4 | AA3: =SUM('BC NGÀY 1'!AB3:AB31) -> 0 | AB3: =SUM('BC NGÀY 1'!AC3:AC31) -> 0 | AC3: =SUM('BC NGÀY 1'!AD3:AD31) -> 0 | AD3: =SUM('BC NGÀY 1'!AE3:AE31) -> 0
A4: 46023 | B4: =SUM('BC NGÀY 1'!C33:C63) -> 0 | C4: =SUM('BC NGÀY 1'!D33:D63) -> 15 | D4: =SUM('BC NGÀY 1'!E33:E63) -> 2 | E4: =SUM('BC NGÀY 1'!F33:F63) -> 2 | F4: =SUM('BC NGÀY 1'!G33:G63) -> 115 | G4: =SUM('BC NGÀY 1'!H33:H63) -> 51 | H4: =SUM('BC NGÀY 1'!I33:I63) -> 2 | I4: =SUM('BC NGÀY 1'!J33:J63) -> 1087 | ... M4: =SUM('BC NGÀY 1'!N33:N63) -> 0 | N4: 2 | O4: =SUM('BC NGÀY 1'!P33:P63) -> 11 | P4: =SUM('BC NGÀY 1'!Q33:Q63) -> 23 | Q4: =SUM('BC NGÀY 1'!R33:R63) -> 5863 | R4: =SUM('BC NGÀY 1'!S33:S63) -> 6200 | S4: =SUM('BC NGÀY 1'!T33:T63) -> 104 | T4: =SUM('BC NGÀY 1'!U33:U63) -> 4331 | U4: =SUM('BC NGÀY 1'!V33:V63) -> 127 | V4: =SUM('BC NGÀY 1'!W33:W63) -> 10194 | ... AD4: =SUM('BC NGÀY 1'!AE33:AE63) -> 0
A5: 46054 | B5: =SUM('BC NGÀY 1'!C64:C93) -> 2 | C5: =SUM('BC NGÀY 1'!D64:D93) -> 39 | D5: =SUM('BC NGÀY 1'!E64:E93) -> 1 | E5: =SUM('BC NGÀY 1'!F64:F93) -> 1 | F5: =SUM('BC NGÀY 1'!G64:G93) -> 206 | G5: =SUM('BC NGÀY 1'!H64:H93) -> 75 | H5: =SUM('BC NGÀY 1'!I64:I93) -> 4 | I5: =SUM('BC NGÀY 1'!J64:J93) -> 2012 | ... AD5: =SUM('BC NGÀY 1'!AE64:AE93) -> 0

Sheet BC CAO ĐIỂM 1
A1: NGÀY | B1: CAO ĐIỂM | C1: VỤ CHÁY VÀ CNCH | G1: CÔNG TÁC KIỂM TRA | P1: TUYÊN TRUYỀN PCCC | T1: HUẤN LUYỆN PCCC | V1: TỔNG TUYÊN TRUYỀN/HUẤN LUYỆN | X1: PACC&CNCH của cơ sở theo mẫu PC06 | Z1: PACC&CNCH của CQ CA theo mẫu PC08 | AB1: PA CNCH của CQ CA theo mẫu PC09 | AD1: PACC&CNCH của phương tiện giao thông theo mẫu PC07
C2: VỤ CHÁY CÓ THỐNG KÊ | D2: SỰ CỐ LIÊN QUAN ĐẾN PCCC&CNCH | E2: VỤ CHÁY CHI VIỆN | F2: CNCH | G2: NHÓM I | H2: NHÓM II | I2: ĐỘT XUẤT | J2: HƯỚNG DẪN | K2: KIẾN NGHỊ | L2: XỬ PHẠT | M2: TIỀN PHẠT (triệu đồng) | N2: ĐÌNH CHỈ | O2: PHỤC HỒI | P2: TIN BÀI, PHÓNG SỰ | Q2: SỐ LỚP TUYÊN TRUYỀN | R2: SỐ NGƯỜI THAM DỰ | S2: SỐ KHUYẾN CÁO, TỜ RƠI ĐÃ PHÁT | T2: SỐ LỚP HUẤN LUYỆN | U2: SỐ NGƯỜI THAM DỰ | V2: SỐ LỚP | W2: SỐ NGƯỜI THAM DỰ | X2: SỐ PA XÂY DỰNG VÀ PHÊ DUYỆT | Y2: SỐ PA ĐƯỢC THỰC TẬP | Z2: SỐ PA XÂY DỰNG VÀ PHÊ DUYỆT | AA2: SỐ PA ĐƯỢC THỰC TẬP | AB2: SỐ PA XÂY DỰNG VÀ PHÊ DUYỆT | AC2: SỐ PA ĐƯỢC THỰC TẬP | AD2: SỐ PA XÂY DỰNG VÀ PHÊ DUYỆT | AE2: SỐ PA ĐƯỢC THỰC TẬP
A3: 15 đến 21/12/2025 | B3: TUẦN 1 | C3: =sum('BC NGÀY 1'!C33:C39) -> 0 | D3: 3 | E3: =sum('BC NGÀY 1'!E33:E39) -> 0 | F3: =sum('BC NGÀY 1'!F33:F39) -> 0 | G3: 8 | H3: 2 | I3: =sum('BC NGÀY 1'!I33:I39) -> 0 | J3: =sum('BC NGÀY 1'!J33:J39) -> 151 | K3: =sum('BC NGÀY 1'!K33:K39) -> 1 | L3: =sum('BC NGÀY 1'!L33:L39) -> 1 | M3: =sum('BC NGÀY 1'!M33:M39) -> 4 | N3: =sum('BC NGÀY 1'!N33:N39) -> 0 | O3: =sum('BC NGÀY 1'!O33:O39) -> 0 | P3: =sum('BC NGÀY 1'!P33:P39) -> 0 | ... W3: =sum('BC NGÀY 1'!W33:W39) -> 3053 | X3: 10 | Y3: 10 | Z3: =sum('BC NGÀY 1'!Z33:Z39) -> 8 | AA3: =sum('BC NGÀY 1'!AA33:AA39) -> 8 | AB3: =sum('BC NGÀY 1'!AB33:AB39) -> 0 | AC3: =sum('BC NGÀY 1'!AC33:AC39) -> 0 | AD3: =sum('BC NGÀY 1'!AD33:AD39) -> 0 | AE3: =sum('BC NGÀY 1'!AE33:AE39) -> 0
A4: 22 đến 30/12/2025 | B4: TUẦN 2 | C4: =sum('BC NGÀY 1'!C40:C48) -> 0 | D4: 2 | E4: =sum('BC NGÀY 1'!E40:E48) -> 1 | F4: =sum('BC NGÀY 1'!F40:F48) -> 1 | G4: =sum('BC NGÀY 1'!G40:G48) -> 12 | H4: =sum('BC NGÀY 1'!H40:H48) -> 6 | I4: =sum('BC NGÀY 1'!I40:I48) -> 0 | J4: =sum('BC NGÀY 1'!J40:J48) -> 24 | K4: =sum('BC NGÀY 1'!K40:K48) -> 0 | L4: =sum('BC NGÀY 1'!L40:L48) -> 0 | ... W4: =sum('BC NGÀY 1'!W40:W48) -> 4123 | X4: 18 | Y4: 18 | Z4: =sum('BC NGÀY 1'!Z40:Z48) -> 8 | AA4: =sum('BC NGÀY 1'!AA40:AA48) -> 8 | AB4: =sum('BC NGÀY 1'!AB40:AB48) -> 0 | AC4: =sum('BC NGÀY 1'!AC40:AC48) -> 0 | AD4: =sum('BC NGÀY 1'!AD40:AD48) -> 0 | AE4: =sum('BC NGÀY 1'!AE40:AE48) -> 0
A5: 15 đến 30/12/25 | B5: Đợt 1 | C5: =sum('BC NGÀY 1'!C33:C48) -> 0 | D5: =sum('BC NGÀY 1'!D33:D48) -> 5 | E5: =sum('BC NGÀY 1'!E33:E48) -> 1 | F5: =sum('BC NGÀY 1'!F33:F48) -> 1 | G5: 20 | H5: 8 | I5: =sum('BC NGÀY 1'!I33:I48) -> 0 | J5: =sum('BC NGÀY 1'!J33:J48) -> 175 | K5: =sum('BC NGÀY 1'!K33:K48) -> 1 | L5: =sum('BC NGÀY 1'!L33:L48) -> 1 | M5: =sum('BC NGÀY 1'!M33:M48) -> 4 | N5: =sum('BC NGÀY 1'!N33:N48) -> 0 | O5: =sum('BC NGÀY 1'!O33:O48) -> 0 | P5: =sum('BC NGÀY 1'!P33:P48) -> 6 | ... W5: =sum('BC NGÀY 1'!W33:W48) -> 7176 | X5: 28 | Y5: 28 | Z5: =sum('BC NGÀY 1'!Z33:Z48) -> 16 | AA5: =sum('BC NGÀY 1'!AA33:AA48) -> 16 | AB5: =sum('BC NGÀY 1'!AB33:AB48) -> 0 | AC5: =sum('BC NGÀY 1'!AC33:AC48) -> 0 | AD5: =sum('BC NGÀY 1'!AD33:AD48) -> 0 | AE5: =sum('BC NGÀY 1'!AE33:AE48) -> 0
A6: 31/12/25 đến 14/01/26 | B6: Đợt 2 | C6: =sum('BC NGÀY 1'!C49:C63) -> 0 | D6: =sum('BC NGÀY 1'!D49:D63) -> 10 | E6: =sum('BC NGÀY 1'!E49:E63) -> 1 | F6: =sum('BC NGÀY 1'!F49:F63) -> 1 | G6: 95 | H6: 43 | I6: =sum('BC NGÀY 1'!I49:I63) -> 2 | J6: =sum('BC NGÀY 1'!J49:J63) -> 912 | K6: =sum('BC NGÀY 1'!K49:K63) -> 4 | L6: =sum('BC NGÀY 1'!L49:L63) -> 4 | M6: =sum('BC NGÀY 1'!M49:M63) -> 108 | N6: =sum('BC NGÀY 1'!N49:N63) -> 0 | O6: =sum('BC NGÀY 1'!O49:O63) -> 0 | P6: =sum('BC NGÀY 1'!P49:P63) -> 5 | ... AE6: =sum('BC NGÀY 1'!AE49:AE63) -> 0
A7: 23 đến 30/01 | B7: TUẦN 6 | C7: =sum('BC NGÀY 1'!C72:C79) -> 0 | D7: =sum('BC NGÀY 1'!D72:D79) -> 12 | E7: =sum('BC NGÀY 1'!E72:E79) -> 0 | F7: =sum('BC NGÀY 1'!F72:F79) -> 0 | G7: =sum('BC NGÀY 1'!G72:G79) -> 31 | H7: =sum('BC NGÀY 1'!H72:H79) -> 15 | I7: =sum('BC NGÀY 1'!I72:I79) -> 1 | J7: =sum('BC NGÀY 1'!J72:J79) -> 371 | ... AE7: =sum('BC NGÀY 1'!AE72:AE79) -> 0
A8: 15 đến 30/01 | B8: Đợt 3 | C8: =sum('BC NGÀY 1'!C64:C79) -> 1 | D8: =sum('BC NGÀY 1'!D64:D79) -> 18 | E8: =sum('BC NGÀY 1'!E64:E79) -> 0 | F8: =sum('BC NGÀY 1'!F64:F79) -> 1 | G8: =sum('BC NGÀY 1'!G64:G79) -> 113 | H8: =sum('BC NGÀY 1'!H64:H79) -> 36 | I8: =sum('BC NGÀY 1'!I64:I79) -> 1 | J8: =sum('BC NGÀY 1'!J64:J79) -> 1112 | ... AE8: =sum('BC NGÀY 1'!AE64:AE79) -> 0
A9: Từ 31/1 - 06/02 | B9: TUẦN 7 | C9: =sum('BC NGÀY 1'!C80:C86) -> 1 | D9: =sum('BC NGÀY 1'!D80:D86) -> 15 | E9: =sum('BC NGÀY 1'!E80:E86) -> 1 | F9: =sum('BC NGÀY 1'!F80:F86) -> 0 | G9: =sum('BC NGÀY 1'!G80:G86) -> 65 | H9: =sum('BC NGÀY 1'!H80:H86) -> 24 | I9: =sum('BC NGÀY 1'!I80:I86) -> 1 | J9: =sum('BC NGÀY 1'!J80:J86) -> 650 | ... AE9: =sum('BC NGÀY 1'!AE80:AE86) -> 0
A10: 31/01 đến 13/02 | B10: Đợt 4 | C10: =sum('BC NGÀY 1'!C80:C93) -> 1 | D10: =sum('BC NGÀY 1'!D80:D93) -> 21 | E10: =sum('BC NGÀY 1'!E80:E93) -> 1 | F10: =sum('BC NGÀY 1'!F80:F93) -> 0 | G10: =sum('BC NGÀY 1'!G80:G93) -> 93 | H10: =sum('BC NGÀY 1'!H80:H93) -> 39 | I10: =sum('BC NGÀY 1'!I80:I93) -> 3 | J10: =sum('BC NGÀY 1'!J80:J93) -> 900 | ... AE10: =sum('BC NGÀY 1'!AE80:AE93) -> 0
A11: Từ 07/02 - 13/02 | B11: TUẦN 8 | C11: =sum('BC NGÀY 1'!C87:C93) -> 0 | D11: =sum('BC NGÀY 1'!D87:D93) -> 6 | E11: =sum('BC NGÀY 1'!E87:E93) -> 0 | F11: =sum('BC NGÀY 1'!F87:F93) -> 0 | G11: =sum('BC NGÀY 1'!G87:G93) -> 28 | H11: =sum('BC NGÀY 1'!H87:H93) -> 15 | I11: =sum('BC NGÀY 1'!I87:I93) -> 2 | J11: =sum('BC NGÀY 1'!J87:J93) -> 250 | ... AE11: =sum('BC NGÀY 1'!AE87:AE93) -> 0
A12: Từ 16/02-18/02 | B12: 03 ngày Tết Nguyên đán | C12: =sum('BC NGÀY 1'!C96:C98) -> 0 | D12: =sum('BC NGÀY 1'!D96:D98) -> 2 | E12: =sum('BC NGÀY 1'!E96:E98) -> 0 | F12: =sum('BC NGÀY 1'!F96:F98) -> 0 | G12: =sum('BC NGÀY 1'!G96:G98) -> 0 | H12: =sum('BC NGÀY 1'!H96:H98) -> 0 | I12: =sum('BC NGÀY 1'!I96:I98) -> 0 | J12: =sum('BC NGÀY 1'!J96:J98) -> 0 | ... AE12: =sum('BC NGÀY 1'!AE96:AE98) -> 0
A13: Từ 14/02-19/02 | B13: 06 ngày Tết Nguyên đán | C13: =sum('BC NGÀY 1'!C94:C99) -> 0 | D13: =sum('BC NGÀY 1'!D94:D99) -> 6 | E13: =sum('BC NGÀY 1'!E94:E99) -> 0 | F13: =sum('BC NGÀY 1'!F94:F99) -> 0 | G13: =sum('BC NGÀY 1'!G94:G99) -> 0 | H13: =sum('BC NGÀY 1'!H94:H99) -> 0 | I13: =sum('BC NGÀY 1'!I94:I99) -> 0 | J13: =sum('BC NGÀY 1'!J94:J99) -> 0 | ... AE13: =sum('BC NGÀY 1'!AE94:AE99) -> 0
